Workbook

Sheet Master
I1: GT | J1: OTC | L1: GT | M1: OTC
H2: DỮ LIỆU TUYẾN | I2: Set | J2: Thực trạng | U2: F2 | V2: F4 | W2: F8
H3: Số Calls tối thiểu tháng | I3: =(I7*6)*4 -> 600 | K3: Tiêu chí | L3: Số lượng cửa hàng trên mỗi nhân viên phải đồng đều nhau: từ 210 - 270 KH
H4: Số Calls tối đa tháng | I4: =(I8*6)*4 -> 720 | L4: Số lượng cửa hàng ghé thăm mỗi ngày: từ 25-30 KH (tần suất 600-720 /tháng) => đảm bảo ghé thăm 100% số cửa hàng mỗi ngày
D5: F0 | E5: 0 | H5: Số cửa hàng tối thiểu/NVBH | I5: 210 | L5: Các khách hàng giữa các Nhân viên, các tuyến phải liên cư liên địa, không chồng lấn
H6: Số cửa hàng tối đa/NVBH | I6: 270 | L6: Doanh số các tuyến cân đối gần tương đương nhau
D7: F1 | E7: 1 | H7: Số cửa hàng tối thiểu/ngày | I7: 25
D8: F3 | E8: 3 | H8: Số cửa hàng tối đa/ngày | I8: 30
A9: =I9 -> 0 | B9: >=0 | C9: ="<"&I10 -> <500000 | D9: F2 | E9: 2 | H9: Doanh số tối thiểu theo tần suất_F2 | I9: 0 | J9: =COUNTIFS(DSKH!$BC:$BC,Master!$B9,DSKH!$BC:$BC,Master!$C9,DSKH!$F:$F,"Hoạt động") -> 466 | L9: Điều chỉnh doanh số để thay đổi tần suất khi thật sự cần thiết (số lượng KH quá nhiều/ quá ít)
A10: =I10 -> 500000 | B10: =">="&I10 -> >=500000 | C10: ="<"&I11 -> <10000000 | D10: F4 | E10: 4 | H10: Doanh số tối thiểu theo tần suất_F4 | I10: 500000 | J10: =COUNTIFS(DSKH!$BC:$BC,Master!$B10,DSKH!$BC:$BC,Master!$C10,DSKH!$F:$F,"Hoạt động") -> 203
A11: =I11 -> 10000000 | B11: =">="&I11 -> >=10000000 | C11: <10000000000 | D11: F8 | E11: 8 | H11: Doanh số tối thiểu theo tần suất_F8 | I11: 10000000 | J11: =COUNTIFS(DSKH!$BC:$BC,Master!$B11,DSKH!$BC:$BC,Master!$C11,DSKH!$F:$F,"Hoạt động") -> 10
H13: Số nhân viên đề xuất | I13: =CONCATENATE(TEXT(SUM($R$16:$R$39)/I4,"#,##0.0")," - ",TEXT(SUM($R$16:$R$39)/I3,"#,##0.0")) -> 2.5 - 3.0 | Z13: Tuần 1 | AN13: Tuần 2 | BB13: Tuần 3 | BP13: Tuần 4
H14: Trung bình mỗi nhân viên | I14: =IFERROR(AVERAGEIFS(I16:I39,I16:I39,">0"),0) -> 1.4620557e+08 | J14: =IFERROR(AVERAGEIFS(J16:J39,J16:J39,">0"),0) -> 1.9871292e+08 | K14: =IFERROR(AVERAGEIFS(K16:K39,K16:K39,">0"),0) -> 1.7245924e+08 | L14: =IFERROR(AVERAGEIFS(L16:L39,L16:L39,">0"),0) -> 190 | M14: =IFERROR(AVERAGEIFS(M16:M39,M16:M39,">0"),0) -> 149.5 | N14: =IFERROR(AVERAGEIFS(N16:N39,N16:N39,">0"),0) -> 169.75 | R14: =IFERROR(AVERAGEIFS(R16:R39,R16:R39,">0"),0) -> 456 | S14: =IFERROR(AVERAGEIFS(S16:S39,S16:S39,">0"),0) -> 13 | T14: =IFERROR(AVERAGEIFS(T16:T39,T16:T39,">0"),0) -> 26 | U14: =SUM(U16:U21) -> 466 | V14: =SUM(V16:V21) -> 226 | W14: =SUM(W16:W21) -> 0 | X14: =IFERROR(AVERAGEIFS(X16:X39,X16:X39,">0"),0) -> 122.25 | Y14: =IFERROR(AVERAGEIFS(Y16:Y39,Y16:Y39,">0"),0) -> 5.75 | Z14: Thứ 2 | AB14: Thứ 3 | AD14: Thứ 4 | AF14: Thứ 5 | AH14: Thứ 6 | AJ14: Thứ 7 | AL14: Tổng Tuần 1 | AN14: Thứ 2 | AP14: Thứ 3 | AR14: Thứ 4 | AT14: Thứ 5 | AV14: Thứ 6 | AX14: Thứ 7 | AZ14: Tổng Tuần 2 | BB14: Thứ 2 | BD14: Thứ 3 | BF14: Thứ 4 | BH14: Thứ 5 | BJ14: Thứ 6 | BL14: Thứ 7 | BN14: Tổng Tuần 3 | BP14: Thứ 2 | BR14: Thứ 3 | BT14: Thứ 4 | BV14: Thứ 5 | BX14: Thứ 6 | BZ14: Thứ 7 | CB14: Tổng Tuần 4
F15: STT | G15: Mã NVBH | H15: Tên NVBH | I15: Doanh số GT | J15: Doanh số OTC | K15: Tổng doanh số trung bình | L15: # khách hàng GT | M15: # khách hàng OTC | N15: # MCP | O15: Số Calls (Tuyến hiện tại) | P15: Call min (Tuyến hiện tại) | Q15: Call Max (Tuyến hiện tại) | R15: Số Calls (chia lại) | S15: Call min (chia lại) | T15: Call Max (chia lại) | U15: # F2 | V15: # F4 | W15: # F8 | X15: Số KH không đúng tần suất (thực trạng DMS) | Y15: Số KH không đúng tần suất (GSBH chia lại) | Z15: # KH | AA15: Doanh số | AB15: # KH | AC15: Doanh số | AD15: # KH | AE15: Doanh số | AF15: # KH | AG15: Doanh số | AH15: # KH | AI15: Doanh số | AJ15: # KH | AK15: Doanh số | AL15: # KH1 | AM15: Doanh số | AN15: # KH | AO15: Doanh số | AP15: # KH | AQ15: Doanh số | AR15: # KH | AS15: Doanh số | AT15: # KH | AU15: Doanh số | AV15: # KH | AW15: Doanh số | AX15: # KH | AY15: Doanh số | AZ15: # KH1 | BA15: Doanh số | BB15: # KH | BC15: Doanh số | BD15: # KH | BE15: Doanh số | BF15: # KH | BG15: Doanh số | BH15: # KH | BI15: Doanh số | BJ15: # KH | BK15: Doanh số | BL15: # KH | BM15: Doanh số | BN15: # KH1 | BO15: Doanh số | BP15: # KH | BQ15: Doanh số | BR15: # KH | BS15: Doanh số | BT15: # KH | BU15: Doanh số | BV15: # KH | BW15: Doanh số | BX15: # KH | BY15: Doanh số | BZ15: # KH | CA15: Doanh số | CB15: # KH1 | CC15: Doanh số
F16: =IF(G16<>"",1,"") -> 1 | G16: {=_xlfn.UNIQUE(_xlfn._xlws.FILTER('Tuyến và nhân viên'!$I:$I,('Tuyến và nhân viên'!$N:$N=1)))} -> HL00622 | H16: {=_xlfn.UNIQUE(_xlfn._xlws.FILTER('Tuyến và nhân viên'!$J:$J,('Tuyến và nhân viên'!$N:$N=1)))} -> Dương Phi Vủ | I16: =IF($G16<>"",SUMIFS('Chi tiết tuyến'!$AE:$AE,'Chi tiết tuyến'!$AD:$AD,Master!I$1,'Chi tiết tuyến'!$AA:$AA,Master!$G16),"") -> 0 | J16: =IF($G16<>"",SUMIFS('Chi tiết tuyến'!$AE:$AE,'Chi tiết tuyến'!$AD:$AD,Master!J$1,'Chi tiết tuyến'!$AA:$AA,Master!$G16),"") -> 2.8614779e+08 | K16: =IF($G16<>"",SUM(I16:J16),"") -> 2.8614779e+08 | L16: =IF($G16<>"",COUNTIFS('Chi tiết tuyến'!$AA:$AA,Master!$G16,'Chi tiết tuyến'!$AD:$AD,Master!L$1),"") -> 0 | M16: =IF($G16<>"",COUNTIFS('Chi tiết tuyến'!$AA:$AA,Master!$G16,'Chi tiết tuyến'!$AD:$AD,Master!M$1),"") -> 142 | N16: =IF($G16<>"",SUM(L16:M16),"") -> 142 | O16: =IF($G16<>"",VLOOKUP($G16,'Tuyến và nhân viên'!$I:$S,9,0),"") -> 572 | P16: =IF($G16<>"",VLOOKUP($G16,'Tuyến và nhân viên'!$I:$S,10,0),"") -> 11 | Q16: =IF($G16<>"",VLOOKUP($G16,'Tuyến và nhân viên'!$I:$S,11,0),"") -> 35 | R16: =IF($G16<>"",SUMIFS('Chi tiết tuyến'!$AJ:$AJ,'Chi tiết tuyến'!$AA:$AA,Master!$G16),"") -> 434 | S16: =IF($G16<>"",_xlfn.MINIFS(Z16:CC16,$Z$15:$CC$15,"# KH"),"") -> 8 | T16: =IF($G16<>"",_xlfn.MAXIFS(Z16:CC16,$Z$15:$CC$15,"# KH"),"") -> 27 | U16: =IF($G16<>"",COUNTIFS('Chi tiết tuyến'!$AG:$AG,U$2,'Chi tiết tuyến'!$AA:$AA,Master!$G16),"") -> 77 | V16: =IF($G16<>"",COUNTIFS('Chi tiết tuyến'!$AG:$AG,V$2,'Chi tiết tuyến'!$AA:$AA,Master!$G16),"") -> 67 | W16: =IF($G16<>"",COUNTIFS('Chi tiết tuyến'!$AG:$AG,W$2,'Chi tiết tuyến'!$AA:$AA,Master!$G16),"") -> 0 | X16: =IF($G16<>"",COUNTIFS('Chi tiết tuyến'!$AH:$AH,FALSE,'Chi tiết tuyến'!$AA:$AA,Master!$G16),"") -> 84 | Y16: =IF($G16<>"",COUNTIFS('Chi tiết tuyến'!$AI:$AI,FALSE,'Chi tiết tuyến'!$AA:$AA,Master!$G16),"") -> 7 | Z16: =IF($G16<>"",COUNTIFS('Chi tiết tuyến'!$AA:$AA,Master!$G16,'Chi tiết tuyến'!L:L,"x",'Chi tiết tuyến'!$W:$W,"x"),"") -> 10 | AA16: =IF($G16<>"",SUMIFS('Chi tiết tuyến'!$BA:$BA,'Chi tiết tuyến'!$AA:$AA,Master!$G16,'Chi tiết tuyến'!$W:$W,"x"),"") -> 1955110.6 | AB16: =IF($G16<>"",COUNTIFS('Chi tiết tuyến'!$AA:$AA,Master!$G16,'Chi tiết tuyến'!M:M,"x",'Chi tiết tuyến'!$W:$W,"x"),"") -> 19 | AC16: =IF($G16<>"",SUMIFS('Chi tiết tuyến'!$BB:$BB,'Chi tiết tuyến'!$AA:$AA,Master!$G16,'Chi tiết tuyến'!$W:$W,"x"),"") -> 4731871.7 | AD16: =IF($G16<>"",COUNTIFS('Chi tiết tuyến'!$AA:$AA,Master!$G16,'Chi tiết tuyến'!N:N,"x",'Chi tiết tuyến'!$W:$W,"x"),"") -> 23 | AE16: =IF($G16<>"",SUMIFS('Chi tiết tuyến'!$BC:$BC,'Chi tiết tuyến'!$AA:$AA,Master!$G16,'Chi tiết tuyến'!$W:$W,"x"),"") -> 6756812.5 | AF16: =IF($G16<>"",COUNTIFS('Chi tiết tuyến'!$AA:$AA,Master!$G16,'Chi tiết tuyến'!O:O,"x",'Chi tiết tuyến'!$W:$W,"x"),"") -> 18 | AG16: =IF($G16<>"",SUMIFS('Chi tiết tuyến'!$BD:$BD,'Chi tiết tuyến'!$AA:$AA,Master!$G16,'Chi tiết tuyến'!$W:$W,"x"),"") -> 11351993 | AH16: =IF($G16<>"",COUNTIFS('Chi tiết tuyến'!$AA:$AA,Master!$G16,'Chi tiết tuyến'!P:P,"x",'Chi tiết tuyến'!$W:$W,"x"),"") -> 12 | AI16: =IF($G16<>"",SUMIFS('Chi tiết tuyến'!$BE:$BE,'Chi tiết tuyến'!$AA:$AA,Master!$G16,'Chi tiết tuyến'!$W:$W,"x"),"") -> 3751098.3 | AJ16: =IF($G16<>"",COUNTIFS('Chi tiết tuyến'!$AA:$AA,Master!$G16,'Chi tiết tuyến'!Q:Q,"x",'Chi tiết tuyến'!$W:$W,"x"),"") -> 27 | AK16: =IF($G16<>"",SUMIFS('Chi tiết tuyến'!$BF:$BF,'Chi tiết tuyến'!$AA:$AA,Master!$G16,'Chi tiết tuyến'!$W:$W,"x"),"") -> 22212941 | AL16: =IF($G16<>"",SUM(Z16,AB16,AD16,AF16,AH16,AJ16),"") -> 109 | AM16: =IF($G16<>"",SUM(AA16,AC16,AE16,AG16,AI16,AK16),"") -> 50759827 | AN16: =IF($G16<>"",COUNTIFS('Chi tiết tuyến'!$AA:$AA,Master!$G16,'Chi tiết tuyến'!L:L,"x",'Chi tiết tuyến'!$X:$X,"x"),"") -> 8 | AO16: =IF($G16<>"",SUMIFS('Chi tiết tuyến'!$BA:$BA,'Chi tiết tuyến'!$AA:$AA,Master!$G16,'Chi tiết tuyến'!$X:$X,"x"),"") -> 1899230.6 | AP16: =IF($G16<>"",COUNTIFS('Chi tiết tuyến'!$AA:$AA,Master!$G16,'Chi tiết tuyến'!M:M,"x",'Chi tiết tuyến'!$X:$X,"x"),"") -> 18 | AQ16: =IF($G16<>"",SUMIFS('Chi tiết tuyến'!$BB:$BB,'Chi tiết tuyến'!$AA:$AA,Master!$G16,'Chi tiết tuyến'!$X:$X,"x"),"") -> 4662018.3 | AR16: =IF($G16<>"",COUNTIFS('Chi tiết tuyến'!$AA:$AA,Master!$G16,'Chi tiết tuyến'!N:N,"x",'Chi tiết tuyến'!$X:$X,"x"),"") -> 22 | AS16: =IF($G16<>"",SUMIFS('Chi tiết tuyến'!$BC:$BC,'Chi tiết tuyến'!$AA:$AA,Master!$G16,'Chi tiết tuyến'!$X:$X,"x"),"") -> 6596442.5 | AT16: =IF($G16<>"",COUNTIFS('Chi tiết tuyến'!$AA:$AA,Master!$G16,'Chi tiết tuyến'!O:O,"x",'Chi tiết tuyến'!$X:$X,"x"),"") -> 17 | AU16: =IF($G16<>"",SUMIFS('Chi tiết tuyến'!$BD:$BD,'Chi tiết tuyến'!$AA:$AA,Master!$G16,'Chi tiết tuyến'!$X:$X,"x"),"") -> 11486626 | AV16: =IF($G16<>"",COUNTIFS('Chi tiết tuyến'!$AA:$AA,Master!$G16,'Chi tiết tuyến'!P:P,"x",'Chi tiết tuyến'!$X:$X,"x"),"") -> 10 | AW16: =IF($G16<>"",SUMIFS('Chi tiết tuyến'!$BE:$BE,'Chi tiết tuyến'!$AA:$AA,Master!$G16,'Chi tiết tuyến'!$X:$X,"x"),"") -> 3513735 | AX16: =IF($G16<>"",COUNTIFS('Chi tiết tuyến'!$AA:$AA,Master!$G16,'Chi tiết tuyến'!Q:Q,"x",'Chi tiết tuyến'!$X:$X,"x"),"") -> 25 | AY16: =IF($G16<>"",SUMIFS('Chi tiết tuyến'!$BF:$BF,'Chi tiết tuyến'!$AA:$AA,Master!$G16,'Chi tiết tuyến'!$X:$X,"x"),"") -> 22438568 | AZ16: =IF($G16<>"",SUM(AN16,AP16,AR16,AT16,AV16,AX16),"") -> 100 | BA16: =IF($G16<>"",SUM(AO16,AQ16,AS16,AU16,AW16,AY16),"") -> 50596621 | BB16: =COUNTIFS('Chi tiết tuyến'!$AA:$AA,Master!$G16,'Chi tiết tuyến'!L:L,"x",'Chi tiết tuyến'!$Y:$Y,"x") -> 10 | BC16: =SUMIFS('Chi tiết tuyến'!$BA:$BA,'Chi tiết tuyến'!$AA:$AA,Master!$G16,'Chi tiết tuyến'!$W:$W,"x") -> 1955110.6 | BD16: =COUNTIFS('Chi tiết tuyến'!$AA:$AA,Master!$G16,'Chi tiết tuyến'!M:M,"x",'Chi tiết tuyến'!$Y:$Y,"x") -> 19 | BE16: =SUMIFS('Chi tiết tuyến'!$BB:$BB,'Chi tiết tuyến'!$AA:$AA,Master!$G16,'Chi tiết tuyến'!$W:$W,"x") -> 4731871.7 | BF16: =COUNTIFS('Chi tiết tuyến'!$AA:$AA,Master!$G16,'Chi tiết tuyến'!N:N,"x",'Chi tiết tuyến'!$Y:$Y,"x") -> 23 | BG16: =SUMIFS('Chi tiết tuyến'!$BC:$BC,'Chi tiết tuyến'!$AA:$AA,Master!$G16,'Chi tiết tuyến'!$W:$W,"x") -> 6756812.5 | BH16: =COUNTIFS('Chi tiết tuyến'!$AA:$AA,Master!$G16,'Chi tiết tuyến'!O:O,"x",'Chi tiết tuyến'!$Y:$Y,"x") -> 18 | BI16: =SUMIFS('Chi tiết tuyến'!$BD:$BD,'Chi tiết tuyến'!$AA:$AA,Master!$G16,'Chi tiết tuyến'!$W:$W,"x") -> 11351993 | BJ16: =COUNTIFS('Chi tiết tuyến'!$AA:$AA,Master!$G16,'Chi tiết tuyến'!P:P,"x",'Chi tiết tuyến'!$Y:$Y,"x") -> 12 | BK16: =SUMIFS('Chi tiết tuyến'!$BE:$BE,'Chi tiết tuyến'!$AA:$AA,Master!$G16,'Chi tiết tuyến'!$W:$W,"x") -> 3751098.3 | BL16: =COUNTIFS('Chi tiết tuyến'!$AA:$AA,Master!$G16,'Chi tiết tuyến'!Q:Q,"x",'Chi tiết tuyến'!$Y:$Y,"x") -> 27 | BM16: =SUMIFS('Chi tiết tuyến'!$BF:$BF,'Chi tiết tuyến'!$AA:$AA,Master!$G16,'Chi tiết tuyến'!$W:$W,"x") -> 22212941 | BN16: =SUM(BB16,BD16,BF16,BH16,BJ16,BL16) -> 109 | BO16: =SUM(BC16,BE16,BG16,BI16,BK16,BM16) -> 50759827 | BP16: =COUNTIFS('Chi tiết tuyến'!$AA:$AA,Master!$G16,'Chi tiết tuyến'!L:L,"x",'Chi tiết tuyến'!$Z:$Z,"x") -> 8 | BQ16: =SUMIFS('Chi tiết tuyến'!$BA:$BA,'Chi tiết tuyến'!$AA:$AA,Master!$G16,'Chi tiết tuyến'!$X:$X,"x") -> 1899230.6 | BR16: =COUNTIFS('Chi tiết tuyến'!$AA:$AA,Master!$G16,'Chi tiết tuyến'!M:M,"x",'Chi tiết tuyến'!$Z:$Z,"x") -> 18 | BS16: =SUMIFS('Chi tiết tuyến'!$BB:$BB,'Chi tiết tuyến'!$AA:$AA,Master!$G16,'Chi tiết tuyến'!$X:$X,"x") -> 4662018.3 | BT16: =COUNTIFS('Chi tiết tuyến'!$AA:$AA,Master!$G16,'Chi tiết tuyến'!N:N,"x",'Chi tiết tuyến'!$Z:$Z,"x") -> 22 | BU16: =SUMIFS('Chi tiết tuyến'!$BC:$BC,'Chi tiết tuyến'!$AA:$AA,Master!$G16,'Chi tiết tuyến'!$X:$X,"x") -> 6596442.5 | BV16: =COUNTIFS('Chi tiết tuyến'!$AA:$AA,Master!$G16,'Chi tiết tuyến'!O:O,"x",'Chi tiết tuyến'!$Z:$Z,"x") -> 17 | BW16: =SUMIFS('Chi tiết tuyến'!$BD:$BD,'Chi tiết tuyến'!$AA:$AA,Master!$G16,'Chi tiết tuyến'!$X:$X,"x") -> 11486626 | BX16: =COUNTIFS('Chi tiết tuyến'!$AA:$AA,Master!$G16,'Chi tiết tuyến'!P:P,"x",'Chi tiết tuyến'!$Z:$Z,"x") -> 10 | BY16: =SUMIFS('Chi tiết tuyến'!$BE:$BE,'Chi tiết tuyến'!$AA:$AA,Master!$G16,'Chi tiết tuyến'!$X:$X,"x") -> 3513735 | BZ16: =COUNTIFS('Chi tiết tuyến'!$AA:$AA,Master!$G16,'Chi tiết tuyến'!Q:Q,"x",'Chi tiết tuyến'!$Z:$Z,"x") -> 25 | CA16: =SUMIFS('Chi tiết tuyến'!$BF:$BF,'Chi tiết tuyến'!$AA:$AA,Master!$G16,'Chi tiết tuyến'!$X:$X,"x") -> 22438568 | CB16: =SUM(BP16,BR16,BT16,BV16,BX16,BZ16) -> 100 | CC16: =SUM(BQ16,BS16,BU16,BW16,BY16,CA16) -> 50596621
F17: =IF(AND(F16>0,G17<>""),F16+1,"") -> 2 | G17: HL00594 | H17: Quách Ngọc Duyên | I17: =IF($G17<>"",SUMIFS('Chi tiết tuyến'!$AE:$AE,'Chi tiết tuyến'!$AD:$AD,Master!I$1,'Chi tiết tuyến'!$AA:$AA,Master!$G17),"") -> 0 | J17: =IF($G17<>"",SUMIFS('Chi tiết tuyến'!$AE:$AE,'Chi tiết tuyến'!$AD:$AD,Master!J$1,'Chi tiết tuyến'!$AA:$AA,Master!$G17),"") -> 1.1127805e+08 | K17: =IF($G17<>"",SUM(I17:J17),"") -> 1.1127805e+08 | L17: =IF($G17<>"",COUNTIFS('Chi tiết tuyến'!$AA:$AA,Master!$G17,'Chi tiết tuyến'!$AD:$AD,Master!L$1),"") -> 0 | M17: =IF($G17<>"",COUNTIFS('Chi tiết tuyến'!$AA:$AA,Master!$G17,'Chi tiết tuyến'!$AD:$AD,Master!M$1),"") -> 157 | N17: =IF($G17<>"",SUM(L17:M17),"") -> 157 | O17: =IF($G17<>"",VLOOKUP($G17,'Tuyến và nhân viên'!$I:$S,9,0),"") -> 648 | P17: =IF($G17<>"",VLOOKUP($G17,'Tuyến và nhân viên'!$I:$S,10,0),"") -> 23 | Q17: =IF($G17<>"",VLOOKUP($G17,'Tuyến và nhân viên'!$I:$S,11,0),"") -> 32 | R17: =IF($G17<>"",SUMIFS('Chi tiết tuyến'!$AJ:$AJ,'Chi tiết tuyến'!$AA:$AA,Master!$G17),"") -> 444 | S17: =IF($G17<>"",_xlfn.MINIFS(Z17:CC17,$Z$15:$CC$15,"# KH"),"") -> 15 | T17: =IF($G17<>"",_xlfn.MAXIFS(Z17:CC17,$Z$15:$CC$15,"# KH"),"") -> 23 | U17: =IF($G17<>"",COUNTIFS('Chi tiết tuyến'!$AG:$AG,U$2,'Chi tiết tuyến'!$AA:$AA,Master!$G17),"") -> 92 | V17: =IF($G17<>"",COUNTIFS('Chi tiết tuyến'!$AG:$AG,V$2,'Chi tiết tuyến'!$AA:$AA,Master!$G17),"") -> 70 | W17: =IF($G17<>"",COUNTIFS('Chi tiết tuyến'!$AG:$AG,W$2,'Chi tiết tuyến'!$AA:$AA,Master!$G17),"") -> 0 | X17: =IF($G17<>"",COUNTIFS('Chi tiết tuyến'!$AH:$AH,FALSE,'Chi tiết tuyến'!$AA:$AA,Master!$G17),"") -> 97 | Y17: =IF($G17<>"",COUNTIFS('Chi tiết tuyến'!$AI:$AI,FALSE,'Chi tiết tuyến'!$AA:$AA,Master!$G17),"") -> 5 | Z17: =IF($G17<>"",COUNTIFS('Chi tiết tuyến'!$AA:$AA,Master!$G17,'Chi tiết tuyến'!L:L,"x",'Chi tiết tuyến'!$W:$W,"x"),"") -> 17 | AA17: =IF($G17<>"",SUMIFS('Chi tiết tuyến'!$BA:$BA,'Chi tiết tuyến'!$AA:$AA,Master!$G17,'Chi tiết tuyến'!$W:$W,"x"),"") -> 4444279.2 | AB17: =IF($G17<>"",COUNTIFS('Chi tiết tuyến'!$AA:$AA,Master!$G17,'Chi tiết tuyến'!M:M,"x",'Chi tiết tuyến'!$W:$W,"x"),"") -> 17 | AC17: =IF($G17<>"",SUMIFS('Chi tiết tuyến'!$BB:$BB,'Chi tiết tuyến'!$AA:$AA,Master!$G17,'Chi tiết tuyến'!$W:$W,"x"),"") -> 3520504.2 | AD17: =IF($G17<>"",COUNTIFS('Chi tiết tuyến'!$AA:$AA,Master!$G17,'Chi tiết tuyến'!N:N,"x",'Chi tiết tuyến'!$W:$W,"x"),"") -> 23 | AE17: =IF($G17<>"",SUMIFS('Chi tiết tuyến'!$BC:$BC,'Chi tiết tuyến'!$AA:$AA,Master!$G17,'Chi tiết tuyến'!$W:$W,"x"),"") -> 4863573.3 | AF17: =IF($G17<>"",COUNTIFS('Chi tiết tuyến'!$AA:$AA,Master!$G17,'Chi tiết tuyến'!O:O,"x",'Chi tiết tuyến'!$W:$W,"x"),"") -> 20 | AG17: =IF($G17<>"",SUMIFS('Chi tiết tuyến'!$BD:$BD,'Chi tiết tuyến'!$AA:$AA,Master!$G17,'Chi tiết tuyến'!$W:$W,"x"),"") -> 6112500.5 | AH17: =IF($G17<>"",COUNTIFS('Chi tiết tuyến'!$AA:$AA,Master!$G17,'Chi tiết tuyến'!P:P,"x",'Chi tiết tuyến'!$W:$W,"x"),"") -> 21 | AI17: =IF($G17<>"",SUMIFS('Chi tiết tuyến'!$BE:$BE,'Chi tiết tuyến'!$AA:$AA,Master!$G17,'Chi tiết tuyến'!$W:$W,"x"),"") -> 3287117.5 | AJ17: =IF($G17<>"",COUNTIFS('Chi tiết tuyến'!$AA:$AA,Master!$G17,'Chi tiết tuyến'!Q:Q,"x",'Chi tiết tuyến'!$W:$W,"x"),"") -> 22 | AK17: =IF($G17<>"",SUMIFS('Chi tiết tuyến'!$BF:$BF,'Chi tiết tuyến'!$AA:$AA,Master!$G17,'Chi tiết tuyến'!$W:$W,"x"),"") -> 6261552.5 | AL17: =IF($G17<>"",SUM(Z17,AB17,AD17,AF17,AH17,AJ17),"") -> 120 | AM17: =IF($G17<>"",SUM(AA17,AC17,AE17,AG17,AI17,AK17),"") -> 28489527 | AN17: =IF($G17<>"",COUNTIFS('Chi tiết tuyến'!$AA:$AA,Master!$G17,'Chi tiết tuyến'!L:L,"x",'Chi tiết tuyến'!$X:$X,"x"),"") -> 15 | AO17: =IF($G17<>"",SUMIFS('Chi tiết tuyến'!$BA:$BA,'Chi tiết tuyến'!$AA:$AA,Master!$G17,'Chi tiết tuyến'!$X:$X,"x"),"") -> 4211582.5 | AP17: =IF($G17<>"",COUNTIFS('Chi tiết tuyến'!$AA:$AA,Master!$G17,'Chi tiết tuyến'!M:M,"x",'Chi tiết tuyến'!$X:$X,"x"),"") -> 16 | AQ17: =IF($G17<>"",SUMIFS('Chi tiết tuyến'!$BB:$BB,'Chi tiết tuyến'!$AA:$AA,Master!$G17,'Chi tiết tuyến'!$X:$X,"x"),"") -> 2995584.2 | AR17: =IF($G17<>"",COUNTIFS('Chi tiết tuyến'!$AA:$AA,Master!$G17,'Chi tiết tuyến'!N:N,"x",'Chi tiết tuyến'!$X:$X,"x"),"") -> 21 | AS17: =IF($G17<>"",SUMIFS('Chi tiết tuyến'!$BC:$BC,'Chi tiết tuyến'!$AA:$AA,Master!$G17,'Chi tiết tuyến'!$X:$X,"x"),"") -> 4817206.7 | AT17: =IF($G17<>"",COUNTIFS('Chi tiết tuyến'!$AA:$AA,Master!$G17,'Chi tiết tuyến'!O:O,"x",'Chi tiết tuyến'!$X:$X,"x"),"") -> 19 | AU17: =IF($G17<>"",SUMIFS('Chi tiết tuyến'!$BD:$BD,'Chi tiết tuyến'!$AA:$AA,Master!$G17,'Chi tiết tuyến'!$X:$X,"x"),"") -> 5985857.2 | AV17: =IF($G17<>"",COUNTIFS('Chi tiết tuyến'!$AA:$AA,Master!$G17,'Chi tiết tuyến'!P:P,"x",'Chi tiết tuyến'!$X:$X,"x"),"") -> 20 | AW17: =IF($G17<>"",SUMIFS('Chi tiết tuyến'!$BE:$BE,'Chi tiết tuyến'!$AA:$AA,Master!$G17,'Chi tiết tuyến'!$X:$X,"x"),"") -> 3474424.2 | AX17: =IF($G17<>"",COUNTIFS('Chi tiết tuyến'!$AA:$AA,Master!$G17,'Chi tiết tuyến'!Q:Q,"x",'Chi tiết tuyến'!$X:$X,"x"),"") -> 21 | AY17: =IF($G17<>"",SUMIFS('Chi tiết tuyến'!$BF:$BF,'Chi tiết tuyến'!$AA:$AA,Master!$G17,'Chi tiết tuyến'!$X:$X,"x"),"") -> 5664840.8 | AZ17: =IF($G17<>"",SUM(AN17,AP17,AR17,AT17,AV17,AX17),"") -> 112 | BA17: =IF($G17<>"",SUM(AO17,AQ17,AS17,AU17,AW17,AY17),"") -> 27149496 | BB17: =COUNTIFS('Chi tiết tuyến'!$AA:$AA,Master!$G17,'Chi tiết tuyến'!L:L,"x",'Chi tiết tuyến'!$Y:$Y,"x") -> 17 | BC17: =SUMIFS('Chi tiết tuyến'!$BA:$BA,'Chi tiết tuyến'!$AA:$AA,Master!$G17,'Chi tiết tuyến'!$W:$W,"x") -> 4444279.2 | BD17: =COUNTIFS('Chi tiết tuyến'!$AA:$AA,Master!$G17,'Chi tiết tuyến'!M:M,"x",'Chi tiết tuyến'!$Y:$Y,"x") -> 17 | BE17: =SUMIFS('Chi tiết tuyến'!$BB:$BB,'Chi tiết tuyến'!$AA:$AA,Master!$G17,'Chi tiết tuyến'!$W:$W,"x") -> 3520504.2 | BF17: =COUNTIFS('Chi tiết tuyến'!$AA:$AA,Master!$G17,'Chi tiết tuyến'!N:N,"x",'Chi tiết tuyến'!$Y:$Y,"x") -> 23 | BG17: =SUMIFS('Chi tiết tuyến'!$BC:$BC,'Chi tiết tuyến'!$AA:$AA,Master!$G17,'Chi tiết tuyến'!$W:$W,"x") -> 4863573.3 | BH17: =COUNTIFS('Chi tiết tuyến'!$AA:$AA,Master!$G17,'Chi tiết tuyến'!O:O,"x",'Chi tiết tuyến'!$Y:$Y,"x") -> 20 | BI17: =SUMIFS('Chi tiết tuyến'!$BD:$BD,'Chi tiết tuyến'!$AA:$AA,Master!$G17,'Chi tiết tuyến'!$W:$W,"x") -> 6112500.5 | BJ17: =COUNTIFS('Chi tiết tuyến'!$AA:$AA,Master!$G17,'Chi tiết tuyến'!P:P,"x",'Chi tiết tuyến'!$Y:$Y,"x") -> 21 | BK17: =SUMIFS('Chi tiết tuyến'!$BE:$BE,'Chi tiết tuyến'!$AA:$AA,Master!$G17,'Chi tiết tuyến'!$W:$W,"x") -> 3287117.5 | BL17: =COUNTIFS('Chi tiết tuyến'!$AA:$AA,Master!$G17,'Chi tiết tuyến'!Q:Q,"x",'Chi tiết tuyến'!$Y:$Y,"x") -> 22 | BM17: =SUMIFS('Chi tiết tuyến'!$BF:$BF,'Chi tiết tuyến'!$AA:$AA,Master!$G17,'Chi tiết tuyến'!$W:$W,"x") -> 6261552.5 | BN17: =SUM(BB17,BD17,BF17,BH17,BJ17,BL17) -> 120 | BO17: =SUM(BC17,BE17,BG17,BI17,BK17,BM17) -> 28489527 | BP17: =COUNTIFS('Chi tiết tuyến'!$AA:$AA,Master!$G17,'Chi tiết tuyến'!L:L,"x",'Chi tiết tuyến'!$Z:$Z,"x") -> 15 | BQ17: =SUMIFS('Chi tiết tuyến'!$BA:$BA,'Chi tiết tuyến'!$AA:$AA,Master!$G17,'Chi tiết tuyến'!$X:$X,"x") -> 4211582.5 | BR17: =COUNTIFS('Chi tiết tuyến'!$AA:$AA,Master!$G17,'Chi tiết tuyến'!M:M,"x",'Chi tiết tuyến'!$Z:$Z,"x") -> 16 | BS17: =SUMIFS('Chi tiết tuyến'!$BB:$BB,'Chi tiết tuyến'!$AA:$AA,Master!$G17,'Chi tiết tuyến'!$X:$X,"x") -> 2995584.2 | BT17: =COUNTIFS('Chi tiết tuyến'!$AA:$AA,Master!$G17,'Chi tiết tuyến'!N:N,"x",'Chi tiết tuyến'!$Z:$Z,"x") -> 21 | BU17: =SUMIFS('Chi tiết tuyến'!$BC:$BC,'Chi tiết tuyến'!$AA:$AA,Master!$G17,'Chi tiết tuyến'!$X:$X,"x") -> 4817206.7 | BV17: =COUNTIFS('Chi tiết tuyến'!$AA:$AA,Master!$G17,'Chi tiết tuyến'!O:O,"x",'Chi tiết tuyến'!$Z:$Z,"x") -> 19 | BW17: =SUMIFS('Chi tiết tuyến'!$BD:$BD,'Chi tiết tuyến'!$AA:$AA,Master!$G17,'Chi tiết tuyến'!$X:$X,"x") -> 5985857.2 | BX17: =COUNTIFS('Chi tiết tuyến'!$AA:$AA,Master!$G17,'Chi tiết tuyến'!P:P,"x",'Chi tiết tuyến'!$Z:$Z,"x") -> 20 | BY17: =SUMIFS('Chi tiết tuyến'!$BE:$BE,'Chi tiết tuyến'!$AA:$AA,Master!$G17,'Chi tiết tuyến'!$X:$X,"x") -> 3474424.2 | BZ17: =COUNTIFS('Chi tiết tuyến'!$AA:$AA,Master!$G17,'Chi tiết tuyến'!Q:Q,"x",'Chi tiết tuyến'!$Z:$Z,"x") -> 21 | CA17: =SUMIFS('Chi tiết tuyến'!$BF:$BF,'Chi tiết tuyến'!$AA:$AA,Master!$G17,'Chi tiết tuyến'!$X:$X,"x") -> 5664840.8 | CB17: =SUM(BP17,BR17,BT17,BV17,BX17,BZ17) -> 112 | CC17: =SUM(BQ17,BS17,BU17,BW17,BY17,CA17) -> 27149496
F18: =IF(AND(F17>0,G18<>""),F17+1,"") -> 3 | G18: HL00530 | H18: Nguyễn Thị Thiên Trang | I18: =IF($G18<>"",SUMIFS('Chi tiết tuyến'!$AE:$AE,'Chi tiết tuyến'!$AD:$AD,Master!I$1,'Chi tiết tuyến'!$AA:$AA,Master!$G18),"") -> 2.0714163e+08 | J18: =IF($G18<>"",SUMIFS('Chi tiết tuyến'!$AE:$AE,'Chi tiết tuyến'!$AD:$AD,Master!J$1,'Chi tiết tuyến'!$AA:$AA,Master!$G18),"") -> 0 | K18: =IF($G18<>"",SUM(I18:J18),"") -> 2.0714163e+08 | L18: =IF($G18<>"",COUNTIFS('Chi tiết tuyến'!$AA:$AA,Master!$G18,'Chi tiết tuyến'!$AD:$AD,Master!L$1),"") -> 198 | M18: =IF($G18<>"",COUNTIFS('Chi tiết tuyến'!$AA:$AA,Master!$G18,'Chi tiết tuyến'!$AD:$AD,Master!M$1),"") -> 0 | N18: =IF($G18<>"",SUM(L18:M18),"") -> 198 | O18: =IF($G18<>"",VLOOKUP($G18,'Tuyến và nhân viên'!$I:$S,9,0),"") -> 792 | P18: =IF($G18<>"",VLOOKUP($G18,'Tuyến và nhân viên'!$I:$S,10,0),"") -> 26 | Q18: =IF($G18<>"",VLOOKUP($G18,'Tuyến và nhân viên'!$I:$S,11,0),"") -> 41 | R18: =IF($G18<>"",SUMIFS('Chi tiết tuyến'!$AJ:$AJ,'Chi tiết tuyến'!$AA:$AA,Master!$G18),"") -> 504 | S18: =IF($G18<>"",_xlfn.MINIFS(Z18:CC18,$Z$15:$CC$15,"# KH"),"") -> 16 | T18: =IF($G18<>"",_xlfn.MAXIFS(Z18:CC18,$Z$15:$CC$15,"# KH"),"") -> 26 | U18: =IF($G18<>"",COUNTIFS('Chi tiết tuyến'!$AG:$AG,U$2,'Chi tiết tuyến'!$AA:$AA,Master!$G18),"") -> 150 | V18: =IF($G18<>"",COUNTIFS('Chi tiết tuyến'!$AG:$AG,V$2,'Chi tiết tuyến'!$AA:$AA,Master!$G18),"") -> 48 | W18: =IF($G18<>"",COUNTIFS('Chi tiết tuyến'!$AG:$AG,W$2,'Chi tiết tuyến'!$AA:$AA,Master!$G18),"") -> 0 | X18: =IF($G18<>"",COUNTIFS('Chi tiết tuyến'!$AH:$AH,FALSE,'Chi tiết tuyến'!$AA:$AA,Master!$G18),"") -> 153 | Y18: =IF($G18<>"",COUNTIFS('Chi tiết tuyến'!$AI:$AI,FALSE,'Chi tiết tuyến'!$AA:$AA,Master!$G18),"") -> 3 | Z18: =IF($G18<>"",COUNTIFS('Chi tiết tuyến'!$AA:$AA,Master!$G18,'Chi tiết tuyến'!L:L,"x",'Chi tiết tuyến'!$W:$W,"x"),"") -> 18 | AA18: =IF($G18<>"",SUMIFS('Chi tiết tuyến'!$BA:$BA,'Chi tiết tuyến'!$AA:$AA,Master!$G18,'Chi tiết tuyến'!$W:$W,"x"),"") -> 3187875.8 | AB18: =IF($G18<>"",COUNTIFS('Chi tiết tuyến'!$AA:$AA,Master!$G18,'Chi tiết tuyến'!M:M,"x",'Chi tiết tuyến'!$W:$W,"x"),"") -> 26 | AC18: =IF($G18<>"",SUMIFS('Chi tiết tuyến'!$BB:$BB,'Chi tiết tuyến'!$AA:$AA,Master!$G18,'Chi tiết tuyến'!$W:$W,"x"),"") -> 4428877.5 | AD18: =IF($G18<>"",COUNTIFS('Chi tiết tuyến'!$AA:$AA,Master!$G18,'Chi tiết tuyến'!N:N,"x",'Chi tiết tuyến'!$W:$W,"x"),"") -> 18 | AE18: =IF($G18<>"",SUMIFS('Chi tiết tuyến'!$BC:$BC,'Chi tiết tuyến'!$AA:$AA,Master!$G18,'Chi tiết tuyến'!$W:$W,"x"),"") -> 10564315 | AF18: =IF($G18<>"",COUNTIFS('Chi tiết tuyến'!$AA:$AA,Master!$G18,'Chi tiết tuyến'!O:O,"x",'Chi tiết tuyến'!$W:$W,"x"),"") -> 23 | AG18: =IF($G18<>"",SUMIFS('Chi tiết tuyến'!$BD:$BD,'Chi tiết tuyến'!$AA:$AA,Master!$G18,'Chi tiết tuyến'!$W:$W,"x"),"") -> 3996698.3 | AH18: =IF($G18<>"",COUNTIFS('Chi tiết tuyến'!$AA:$AA,Master!$G18,'Chi tiết tuyến'!P:P,"x",'Chi tiết tuyến'!$W:$W,"x"),"") -> 20 | AI18: =IF($G18<>"",SUMIFS('Chi tiết tuyến'!$BE:$BE,'Chi tiết tuyến'!$AA:$AA,Master!$G18,'Chi tiết tuyến'!$W:$W,"x"),"") -> 2226605.8 | AJ18: =IF($G18<>"",COUNTIFS('Chi tiết tuyến'!$AA:$AA,Master!$G18,'Chi tiết tuyến'!Q:Q,"x",'Chi tiết tuyến'!$W:$W,"x"),"") -> 24 | AK18: =IF($G18<>"",SUMIFS('Chi tiết tuyến'!$BF:$BF,'Chi tiết tuyến'!$AA:$AA,Master!$G18,'Chi tiết tuyến'!$W:$W,"x"),"") -> 15542057 | AL18: =IF($G18<>"",SUM(Z18,AB18,AD18,AF18,AH18,AJ18),"") -> 129 | AM18: =IF($G18<>"",SUM(AA18,AC18,AE18,AG18,AI18,AK18),"") -> 39946429 | AN18: =IF($G18<>"",COUNTIFS('Chi tiết tuyến'!$AA:$AA,Master!$G18,'Chi tiết tuyến'!L:L,"x",'Chi tiết tuyến'!$X:$X,"x"),"") -> 16 | AO18: =IF($G18<>"",SUMIFS('Chi tiết tuyến'!$BA:$BA,'Chi tiết tuyến'!$AA:$AA,Master!$G18,'Chi tiết tuyến'!$X:$X,"x"),"") -> 3171950.8 | AP18: =IF($G18<>"",COUNTIFS('Chi tiết tuyến'!$AA:$AA,Master!$G18,'Chi tiết tuyến'!M:M,"x",'Chi tiết tuyến'!$X:$X,"x"),"") -> 24 | AQ18: =IF($G18<>"",SUMIFS('Chi tiết tuyến'!$BB:$BB,'Chi tiết tuyến'!$AA:$AA,Master!$G18,'Chi tiết tuyến'!$X:$X,"x"),"") -> 4247465.8 | AR18: =IF($G18<>"",COUNTIFS('Chi tiết tuyến'!$AA:$AA,Master!$G18,'Chi tiết tuyến'!N:N,"x",'Chi tiết tuyến'!$X:$X,"x"),"") -> 16 | AS18: =IF($G18<>"",SUMIFS('Chi tiết tuyến'!$BC:$BC,'Chi tiết tuyến'!$AA:$AA,Master!$G18,'Chi tiết tuyến'!$X:$X,"x"),"") -> 11005378 | AT18: =IF($G18<>"",COUNTIFS('Chi tiết tuyến'!$AA:$AA,Master!$G18,'Chi tiết tuyến'!O:O,"x",'Chi tiết tuyến'!$X:$X,"x"),"") -> 21 | AU18: =IF($G18<>"",SUMIFS('Chi tiết tuyến'!$BD:$BD,'Chi tiết tuyến'!$AA:$AA,Master!$G18,'Chi tiết tuyến'!$X:$X,"x"),"") -> 4115240 | AV18: =IF($G18<>"",COUNTIFS('Chi tiết tuyến'!$AA:$AA,Master!$G18,'Chi tiết tuyến'!P:P,"x",'Chi tiết tuyến'!$X:$X,"x"),"") -> 18 | AW18: =IF($G18<>"",SUMIFS('Chi tiết tuyến'!$BE:$BE,'Chi tiết tuyến'!$AA:$AA,Master!$G18,'Chi tiết tuyến'!$X:$X,"x"),"") -> 2453314.2 | AX18: =IF($G18<>"",COUNTIFS('Chi tiết tuyến'!$AA:$AA,Master!$G18,'Chi tiết tuyến'!Q:Q,"x",'Chi tiết tuyến'!$X:$X,"x"),"") -> 22 | AY18: =IF($G18<>"",SUMIFS('Chi tiết tuyến'!$BF:$BF,'Chi tiết tuyến'!$AA:$AA,Master!$G18,'Chi tiết tuyến'!$X:$X,"x"),"") -> 15512510 | AZ18: =IF($G18<>"",SUM(AN18,AP18,AR18,AT18,AV18,AX18),"") -> 117 | BA18: =IF($G18<>"",SUM(AO18,AQ18,AS18,AU18,AW18,AY18),"") -> 40505859 | BB18: =COUNTIFS('Chi tiết tuyến'!$AA:$AA,Master!$G18,'Chi tiết tuyến'!L:L,"x",'Chi tiết tuyến'!$Y:$Y,"x") -> 18 | BC18: =SUMIFS('Chi tiết tuyến'!$BA:$BA,'Chi tiết tuyến'!$AA:$AA,Master!$G18,'Chi tiết tuyến'!$W:$W,"x") -> 3187875.8 | BD18: =COUNTIFS('Chi tiết tuyến'!$AA:$AA,Master!$G18,'Chi tiết tuyến'!M:M,"x",'Chi tiết tuyến'!$Y:$Y,"x") -> 26 | BE18: =SUMIFS('Chi tiết tuyến'!$BB:$BB,'Chi tiết tuyến'!$AA:$AA,Master!$G18,'Chi tiết tuyến'!$W:$W,"x") -> 4428877.5 | BF18: =COUNTIFS('Chi tiết tuyến'!$AA:$AA,Master!$G18,'Chi tiết tuyến'!N:N,"x",'Chi tiết tuyến'!$Y:$Y,"x") -> 18 | BG18: =SUMIFS('Chi tiết tuyến'!$BC:$BC,'Chi tiết tuyến'!$AA:$AA,Master!$G18,'Chi tiết tuyến'!$W:$W,"x") -> 10564315 | BH18: =COUNTIFS('Chi tiết tuyến'!$AA:$AA,Master!$G18,'Chi tiết tuyến'!O:O,"x",'Chi tiết tuyến'!$Y:$Y,"x") -> 23 | BI18: =SUMIFS('Chi tiết tuyến'!$BD:$BD,'Chi tiết tuyến'!$AA:$AA,Master!$G18,'Chi tiết tuyến'!$W:$W,"x") -> 3996698.3 | BJ18: =COUNTIFS('Chi tiết tuyến'!$AA:$AA,Master!$G18,'Chi tiết tuyến'!P:P,"x",'Chi tiết tuyến'!$Y:$Y,"x") -> 20 | BK18: =SUMIFS('Chi tiết tuyến'!$BE:$BE,'Chi tiết tuyến'!$AA:$AA,Master!$G18,'Chi tiết tuyến'!$W:$W,"x") -> 2226605.8 | BL18: =COUNTIFS('Chi tiết tuyến'!$AA:$AA,Master!$G18,'Chi tiết tuyến'!Q:Q,"x",'Chi tiết tuyến'!$Y:$Y,"x") -> 24 | BM18: =SUMIFS('Chi tiết tuyến'!$BF:$BF,'Chi tiết tuyến'!$AA:$AA,Master!$G18,'Chi tiết tuyến'!$W:$W,"x") -> 15542057 | BN18: =SUM(BB18,BD18,BF18,BH18,BJ18,BL18) -> 129 | BO18: =SUM(BC18,BE18,BG18,BI18,BK18,BM18) -> 39946429 | BP18: =COUNTIFS('Chi tiết tuyến'!$AA:$AA,Master!$G18,'Chi tiết tuyến'!L:L,"x",'Chi tiết tuyến'!$Z:$Z,"x") -> 16 | BQ18: =SUMIFS('Chi tiết tuyến'!$BA:$BA,'Chi tiết tuyến'!$AA:$AA,Master!$G18,'Chi tiết tuyến'!$X:$X,"x") -> 3171950.8 | BR18: =COUNTIFS('Chi tiết tuyến'!$AA:$AA,Master!$G18,'Chi tiết tuyến'!M:M,"x",'Chi tiết tuyến'!$Z:$Z,"x") -> 24 | BS18: =SUMIFS('Chi tiết tuyến'!$BB:$BB,'Chi tiết tuyến'!$AA:$AA,Master!$G18,'Chi tiết tuyến'!$X:$X,"x") -> 4247465.8 | BT18: =COUNTIFS('Chi tiết tuyến'!$AA:$AA,Master!$G18,'Chi tiết tuyến'!N:N,"x",'Chi tiết tuyến'!$Z:$Z,"x") -> 16 | BU18: =SUMIFS('Chi tiết tuyến'!$BC:$BC,'Chi tiết tuyến'!$AA:$AA,Master!$G18,'Chi tiết tuyến'!$X:$X,"x") -> 11005378 | BV18: =COUNTIFS('Chi tiết tuyến'!$AA:$AA,Master!$G18,'Chi tiết tuyến'!O:O,"x",'Chi tiết tuyến'!$Z:$Z,"x") -> 21 | BW18: =SUMIFS('Chi tiết tuyến'!$BD:$BD,'Chi tiết tuyến'!$AA:$AA,Master!$G18,'Chi tiết tuyến'!$X:$X,"x") -> 4115240 | BX18: =COUNTIFS('Chi tiết tuyến'!$AA:$AA,Master!$G18,'Chi tiết tuyến'!P:P,"x",'Chi tiết tuyến'!$Z:$Z,"x") -> 18 | BY18: =SUMIFS('Chi tiết tuyến'!$BE:$BE,'Chi tiết tuyến'!$AA:$AA,Master!$G18,'Chi tiết tuyến'!$X:$X,"x") -> 2453314.2 | BZ18: =COUNTIFS('Chi tiết tuyến'!$AA:$AA,Master!$G18,'Chi tiết tuyến'!Q:Q,"x",'Chi tiết tuyến'!$Z:$Z,"x") -> 22 | CA18: =SUMIFS('Chi tiết tuyến'!$BF:$BF,'Chi tiết tuyến'!$AA:$AA,Master!$G18,'Chi tiết tuyến'!$X:$X,"x") -> 15512510 | CB18: =SUM(BP18,BR18,BT18,BV18,BX18,BZ18) -> 117 | CC18: =SUM(BQ18,BS18,BU18,BW18,BY18,CA18) -> 40505859
F19: =IF(AND(F18>0,G19<>""),F18+1,"") -> 4 | G19: HL00623 | H19: Lê Thị Liên Thư | I19: =IF($G19<>"",SUMIFS('Chi tiết tuyến'!$AE:$AE,'Chi tiết tuyến'!$AD:$AD,Master!I$1,'Chi tiết tuyến'!$AA:$AA,Master!$G19),"") -> 85269520 | J19: =IF($G19<>"",SUMIFS('Chi tiết tuyến'!$AE:$AE,'Chi tiết tuyến'!$AD:$AD,Master!J$1,'Chi tiết tuyến'!$AA:$AA,Master!$G19),"") -> 0 | K19: =IF($G19<>"",SUM(I19:J19),"") -> 85269520 | L19: =IF($G19<>"",COUNTIFS('Chi tiết tuyến'!$AA:$AA,Master!$G19,'Chi tiết tuyến'!$AD:$AD,Master!L$1),"") -> 182 | M19: =IF($G19<>"",COUNTIFS('Chi tiết tuyến'!$AA:$AA,Master!$G19,'Chi tiết tuyến'!$AD:$AD,Master!M$1),"") -> 0 | N19: =IF($G19<>"",SUM(L19:M19),"") -> 182 | O19: =IF($G19<>"",VLOOKUP($G19,'Tuyến và nhân viên'!$I:$S,9,0),"") -> 752 | P19: =IF($G19<>"",VLOOKUP($G19,'Tuyến và nhân viên'!$I:$S,10,0),"") -> 22 | Q19: =IF($G19<>"",VLOOKUP($G19,'Tuyến và nhân viên'!$I:$S,11,0),"") -> 47 | R19: =IF($G19<>"",SUMIFS('Chi tiết tuyến'!$AJ:$AJ,'Chi tiết tuyến'!$AA:$AA,Master!$G19),"") -> 442 | S19: =IF($G19<>"",_xlfn.MINIFS(Z19:CC19,$Z$15:$CC$15,"# KH"),"") -> 13 | T19: =IF($G19<>"",_xlfn.MAXIFS(Z19:CC19,$Z$15:$CC$15,"# KH"),"") -> 28 | U19: =IF($G19<>"",COUNTIFS('Chi tiết tuyến'!$AG:$AG,U$2,'Chi tiết tuyến'!$AA:$AA,Master!$G19),"") -> 147 | V19: =IF($G19<>"",COUNTIFS('Chi tiết tuyến'!$AG:$AG,V$2,'Chi tiết tuyến'!$AA:$AA,Master!$G19),"") -> 41 | W19: =IF($G19<>"",COUNTIFS('Chi tiết tuyến'!$AG:$AG,W$2,'Chi tiết tuyến'!$AA:$AA,Master!$G19),"") -> 0 | X19: =IF($G19<>"",COUNTIFS('Chi tiết tuyến'!$AH:$AH,FALSE,'Chi tiết tuyến'!$AA:$AA,Master!$G19),"") -> 155 | Y19: =IF($G19<>"",COUNTIFS('Chi tiết tuyến'!$AI:$AI,FALSE,'Chi tiết tuyến'!$AA:$AA,Master!$G19),"") -> 8 | Z19: =IF($G19<>"",COUNTIFS('Chi tiết tuyến'!$AA:$AA,Master!$G19,'Chi tiết tuyến'!L:L,"x",'Chi tiết tuyến'!$W:$W,"x"),"") -> 18 | AA19: =IF($G19<>"",SUMIFS('Chi tiết tuyến'!$BA:$BA,'Chi tiết tuyến'!$AA:$AA,Master!$G19,'Chi tiết tuyến'!$W:$W,"x"),"") -> 2735430 | AB19: =IF($G19<>"",COUNTIFS('Chi tiết tuyến'!$AA:$AA,Master!$G19,'Chi tiết tuyến'!M:M,"x",'Chi tiết tuyến'!$W:$W,"x"),"") -> 15 | AC19: =IF($G19<>"",SUMIFS('Chi tiết tuyến'!$BB:$BB,'Chi tiết tuyến'!$AA:$AA,Master!$G19,'Chi tiết tuyến'!$W:$W,"x"),"") -> 2097630.8 | AD19: =IF($G19<>"",COUNTIFS('Chi tiết tuyến'!$AA:$AA,Master!$G19,'Chi tiết tuyến'!N:N,"x",'Chi tiết tuyến'!$W:$W,"x"),"") -> 26 | AE19: =IF($G19<>"",SUMIFS('Chi tiết tuyến'!$BC:$BC,'Chi tiết tuyến'!$AA:$AA,Master!$G19,'Chi tiết tuyến'!$W:$W,"x"),"") -> 3717993.3 | AF19: =IF($G19<>"",COUNTIFS('Chi tiết tuyến'!$AA:$AA,Master!$G19,'Chi tiết tuyến'!O:O,"x",'Chi tiết tuyến'!$W:$W,"x"),"") -> 18 | AG19: =IF($G19<>"",SUMIFS('Chi tiết tuyến'!$BD:$BD,'Chi tiết tuyến'!$AA:$AA,Master!$G19,'Chi tiết tuyến'!$W:$W,"x"),"") -> 1908910 | AH19: =IF($G19<>"",COUNTIFS('Chi tiết tuyến'!$AA:$AA,Master!$G19,'Chi tiết tuyến'!P:P,"x",'Chi tiết tuyến'!$W:$W,"x"),"") -> 15 | AI19: =IF($G19<>"",SUMIFS('Chi tiết tuyến'!$BE:$BE,'Chi tiết tuyến'!$AA:$AA,Master!$G19,'Chi tiết tuyến'!$W:$W,"x"),"") -> 556033.33 | AJ19: =IF($G19<>"",COUNTIFS('Chi tiết tuyến'!$AA:$AA,Master!$G19,'Chi tiết tuyến'!Q:Q,"x",'Chi tiết tuyến'!$W:$W,"x"),"") -> 28 | AK19: =IF($G19<>"",SUMIFS('Chi tiết tuyến'!$BF:$BF,'Chi tiết tuyến'!$AA:$AA,Master!$G19,'Chi tiết tuyến'!$W:$W,"x"),"") -> 6217572.5 | AL19: =IF($G19<>"",SUM(Z19,AB19,AD19,AF19,AH19,AJ19),"") -> 120 | AM19: =IF($G19<>"",SUM(AA19,AC19,AE19,AG19,AI19,AK19),"") -> 17233570 | AN19: =IF($G19<>"",COUNTIFS('Chi tiết tuyến'!$AA:$AA,Master!$G19,'Chi tiết tuyến'!L:L,"x",'Chi tiết tuyến'!$X:$X,"x"),"") -> 16 | AO19: =IF($G19<>"",SUMIFS('Chi tiết tuyến'!$BA:$BA,'Chi tiết tuyến'!$AA:$AA,Master!$G19,'Chi tiết tuyến'!$X:$X,"x"),"") -> 2976096.7 | AP19: =IF($G19<>"",COUNTIFS('Chi tiết tuyến'!$AA:$AA,Master!$G19,'Chi tiết tuyến'!M:M,"x",'Chi tiết tuyến'!$X:$X,"x"),"") -> 13 | AQ19: =IF($G19<>"",SUMIFS('Chi tiết tuyến'!$BB:$BB,'Chi tiết tuyến'!$AA:$AA,Master!$G19,'Chi tiết tuyến'!$X:$X,"x"),"") -> 1879827.5 | AR19: =IF($G19<>"",COUNTIFS('Chi tiết tuyến'!$AA:$AA,Master!$G19,'Chi tiết tuyến'!N:N,"x",'Chi tiết tuyến'!$X:$X,"x"),"") -> 24 | AS19: =IF($G19<>"",SUMIFS('Chi tiết tuyến'!$BC:$BC,'Chi tiết tuyến'!$AA:$AA,Master!$G19,'Chi tiết tuyến'!$X:$X,"x"),"") -> 3757200 | AT19: =IF($G19<>"",COUNTIFS('Chi tiết tuyến'!$AA:$AA,Master!$G19,'Chi tiết tuyến'!O:O,"x",'Chi tiết tuyến'!$X:$X,"x"),"") -> 17 | AU19: =IF($G19<>"",SUMIFS('Chi tiết tuyến'!$BD:$BD,'Chi tiết tuyến'!$AA:$AA,Master!$G19,'Chi tiết tuyến'!$X:$X,"x"),"") -> 1603013.3 | AV19: =IF($G19<>"",COUNTIFS('Chi tiết tuyến'!$AA:$AA,Master!$G19,'Chi tiết tuyến'!P:P,"x",'Chi tiết tuyến'!$X:$X,"x"),"") -> 13 | AW19: =IF($G19<>"",SUMIFS('Chi tiết tuyến'!$BE:$BE,'Chi tiết tuyến'!$AA:$AA,Master!$G19,'Chi tiết tuyến'!$X:$X,"x"),"") -> 488025 | AX19: =IF($G19<>"",COUNTIFS('Chi tiết tuyến'!$AA:$AA,Master!$G19,'Chi tiết tuyến'!Q:Q,"x",'Chi tiết tuyến'!$X:$X,"x"),"") -> 26 | AY19: =IF($G19<>"",SUMIFS('Chi tiết tuyến'!$BF:$BF,'Chi tiết tuyến'!$AA:$AA,Master!$G19,'Chi tiết tuyến'!$X:$X,"x"),"") -> 6226322.5 | AZ19: =IF($G19<>"",SUM(AN19,AP19,AR19,AT19,AV19,AX19),"") -> 109 | BA19: =IF($G19<>"",SUM(AO19,AQ19,AS19,AU19,AW19,AY19),"") -> 16930485 | BB19: =COUNTIFS('Chi tiết tuyến'!$AA:$AA,Master!$G19,'Chi tiết tuyến'!L:L,"x",'Chi tiết tuyến'!$Y:$Y,"x") -> 18 | BC19: =SUMIFS('Chi tiết tuyến'!$BA:$BA,'Chi tiết tuyến'!$AA:$AA,Master!$G19,'Chi tiết tuyến'!$W:$W,"x") -> 2735430 | BD19: =COUNTIFS('Chi tiết tuyến'!$AA:$AA,Master!$G19,'Chi tiết tuyến'!M:M,"x",'Chi tiết tuyến'!$Y:$Y,"x") -> 15 | BE19: =SUMIFS('Chi tiết tuyến'!$BB:$BB,'Chi tiết tuyến'!$AA:$AA,Master!$G19,'Chi tiết tuyến'!$W:$W,"x") -> 2097630.8 | BF19: =COUNTIFS('Chi tiết tuyến'!$AA:$AA,Master!$G19,'Chi tiết tuyến'!N:N,"x",'Chi tiết tuyến'!$Y:$Y,"x") -> 26 | BG19: =SUMIFS('Chi tiết tuyến'!$BC:$BC,'Chi tiết tuyến'!$AA:$AA,Master!$G19,'Chi tiết tuyến'!$W:$W,"x") -> 3717993.3 | BH19: =COUNTIFS('Chi tiết tuyến'!$AA:$AA,Master!$G19,'Chi tiết tuyến'!O:O,"x",'Chi tiết tuyến'!$Y:$Y,"x") -> 18 | BI19: =SUMIFS('Chi tiết tuyến'!$BD:$BD,'Chi tiết tuyến'!$AA:$AA,Master!$G19,'Chi tiết tuyến'!$W:$W,"x") -> 1908910 | BJ19: =COUNTIFS('Chi tiết tuyến'!$AA:$AA,Master!$G19,'Chi tiết tuyến'!P:P,"x",'Chi tiết tuyến'!$Y:$Y,"x") -> 15 | BK19: =SUMIFS('Chi tiết tuyến'!$BE:$BE,'Chi tiết tuyến'!$AA:$AA,Master!$G19,'Chi tiết tuyến'!$W:$W,"x") -> 556033.33 | BL19: =COUNTIFS('Chi tiết tuyến'!$AA:$AA,Master!$G19,'Chi tiết tuyến'!Q:Q,"x",'Chi tiết tuyến'!$Y:$Y,"x") -> 28 | BM19: =SUMIFS('Chi tiết tuyến'!$BF:$BF,'Chi tiết tuyến'!$AA:$AA,Master!$G19,'Chi tiết tuyến'!$W:$W,"x") -> 6217572.5 | BN19: =SUM(BB19,BD19,BF19,BH19,BJ19,BL19) -> 120 | BO19: =SUM(BC19,BE19,BG19,BI19,BK19,BM19) -> 17233570 | BP19: =COUNTIFS('Chi tiết tuyến'!$AA:$AA,Master!$G19,'Chi tiết tuyến'!L:L,"x",'Chi tiết tuyến'!$Z:$Z,"x") -> 16 | BQ19: =SUMIFS('Chi tiết tuyến'!$BA:$BA,'Chi tiết tuyến'!$AA:$AA,Master!$G19,'Chi tiết tuyến'!$X:$X,"x") -> 2976096.7 | BR19: =COUNTIFS('Chi tiết tuyến'!$AA:$AA,Master!$G19,'Chi tiết tuyến'!M:M,"x",'Chi tiết tuyến'!$Z:$Z,"x") -> 13 | BS19: =SUMIFS('Chi tiết tuyến'!$BB:$BB,'Chi tiết tuyến'!$AA:$AA,Master!$G19,'Chi tiết tuyến'!$X:$X,"x") -> 1879827.5 | BT19: =COUNTIFS('Chi tiết tuyến'!$AA:$AA,Master!$G19,'Chi tiết tuyến'!N:N,"x",'Chi tiết tuyến'!$Z:$Z,"x") -> 24 | BU19: =SUMIFS('Chi tiết tuyến'!$BC:$BC,'Chi tiết tuyến'!$AA:$AA,Master!$G19,'Chi tiết tuyến'!$X:$X,"x") -> 3757200 | BV19: =COUNTIFS('Chi tiết tuyến'!$AA:$AA,Master!$G19,'Chi tiết tuyến'!O:O,"x",'Chi tiết tuyến'!$Z:$Z,"x") -> 17 | BW19: =SUMIFS('Chi tiết tuyến'!$BD:$BD,'Chi tiết tuyến'!$AA:$AA,Master!$G19,'Chi tiết tuyến'!$X:$X,"x") -> 1603013.3 | BX19: =COUNTIFS('Chi tiết tuyến'!$AA:$AA,Master!$G19,'Chi tiết tuyến'!P:P,"x",'Chi tiết tuyến'!$Z:$Z,"x") -> 13 | BY19: =SUMIFS('Chi tiết tuyến'!$BE:$BE,'Chi tiết tuyến'!$AA:$AA,Master!$G19,'Chi tiết tuyến'!$X:$X,"x") -> 488025 | BZ19: =COUNTIFS('Chi tiết tuyến'!$AA:$AA,Master!$G19,'Chi tiết tuyến'!Q:Q,"x",'Chi tiết tuyến'!$Z:$Z,"x") -> 26 | CA19: =SUMIFS('Chi tiết tuyến'!$BF:$BF,'Chi tiết tuyến'!$AA:$AA,Master!$G19,'Chi tiết tuyến'!$X:$X,"x") -> 6226322.5 | CB19: =SUM(BP19,BR19,BT19,BV19,BX19,BZ19) -> 109 | CC19: =SUM(BQ19,BS19,BU19,BW19,BY19,CA19) -> 16930485
F20: =IF(AND(F19>0,G20<>""),F19+1,"") | I20: =IF($G20<>"",SUMIFS('Chi tiết tuyến'!$AE:$AE,'Chi tiết tuyến'!$AD:$AD,Master!I$1,'Chi tiết tuyến'!$AA:$AA,Master!$G20),"") | J20: =IF($G20<>"",SUMIFS('Chi tiết tuyến'!$AE:$AE,'Chi tiết tuyến'!$AD:$AD,Master!J$1,'Chi tiết tuyến'!$AA:$AA,Master!$G20),"") | K20: =IF($G20<>"",SUM(I20:J20),"") | L20: =IF($G20<>"",COUNTIFS('Chi tiết tuyến'!$AA:$AA,Master!$G20,'Chi tiết tuyến'!$AD:$AD,Master!L$1),"") | M20: =IF($G20<>"",COUNTIFS('Chi tiết tuyến'!$AA:$AA,Master!$G20,'Chi tiết tuyến'!$AD:$AD,Master!M$1),"") | N20: =IF($G20<>"",SUM(L20:M20),"") | O20: =IF($G20<>"",VLOOKUP($G20,'Tuyến và nhân viên'!$I:$S,9,0),"") | P20: =IF($G20<>"",VLOOKUP($G20,'Tuyến và nhân viên'!$I:$S,10,0),"") | Q20: =IF($G20<>"",VLOOKUP($G20,'Tuyến và nhân viên'!$I:$S,11,0),"") | R20: =IF($G20<>"",SUMIFS('Chi tiết tuyến'!$AJ:$AJ,'Chi tiết tuyến'!$AA:$AA,Master!$G20),"") | S20: =IF($G20<>"",_xlfn.MINIFS(Z20:CC20,$Z$15:$CC$15,"# KH"),"") | T20: =IF($G20<>"",_xlfn.MAXIFS(Z20:CC20,$Z$15:$CC$15,"# KH"),"") | U20: =IF($G20<>"",COUNTIFS('Chi tiết tuyến'!$AG:$AG,U$2,'Chi tiết tuyến'!$AA:$AA,Master!$G20),"") | V20: =IF($G20<>"",COUNTIFS('Chi tiết tuyến'!$AG:$AG,V$2,'Chi tiết tuyến'!$AA:$AA,Master!$G20),"") | W20: =IF($G20<>"",COUNTIFS('Chi tiết tuyến'!$AG:$AG,W$2,'Chi tiết tuyến'!$AA:$AA,Master!$G20),"") | X20: =IF($G20<>"",COUNTIFS('Chi tiết tuyến'!$AH:$AH,FALSE,'Chi tiết tuyến'!$AA:$AA,Master!$G20),"") | Y20: =IF($G20<>"",COUNTIFS('Chi tiết tuyến'!$AI:$AI,FALSE,'Chi tiết tuyến'!$AA:$AA,Master!$G20),"") | Z20: =IF($G20<>"",COUNTIFS('Chi tiết tuyến'!$AA:$AA,Master!$G20,'Chi tiết tuyến'!L:L,"x",'Chi tiết tuyến'!$W:$W,"x"),"") | AA20: =IF($G20<>"",SUMIFS('Chi tiết tuyến'!$BA:$BA,'Chi tiết tuyến'!$AA:$AA,Master!$G20,'Chi tiết tuyến'!$W:$W,"x"),"") | AB20: =IF($G20<>"",COUNTIFS('Chi tiết tuyến'!$AA:$AA,Master!$G20,'Chi tiết tuyến'!M:M,"x",'Chi tiết tuyến'!$W:$W,"x"),"") | AC20: =IF($G20<>"",SUMIFS('Chi tiết tuyến'!$BB:$BB,'Chi tiết tuyến'!$AA:$AA,Master!$G20,'Chi tiết tuyến'!$W:$W,"x"),"") | AD20: =IF($G20<>"",COUNTIFS('Chi tiết tuyến'!$AA:$AA,Master!$G20,'Chi tiết tuyến'!N:N,"x",'Chi tiết tuyến'!$W:$W,"x"),"") | AE20: =IF($G20<>"",SUMIFS('Chi tiết tuyến'!$BC:$BC,'Chi tiết tuyến'!$AA:$AA,Master!$G20,'Chi tiết tuyến'!$W:$W,"x"),"") | AF20: =IF($G20<>"",COUNTIFS('Chi tiết tuyến'!$AA:$AA,Master!$G20,'Chi tiết tuyến'!O:O,"x",'Chi tiết tuyến'!$W:$W,"x"),"") | AG20: =IF($G20<>"",SUMIFS('Chi tiết tuyến'!$BD:$BD,'Chi tiết tuyến'!$AA:$AA,Master!$G20,'Chi tiết tuyến'!$W:$W,"x"),"") | AH20: =IF($G20<>"",COUNTIFS('Chi tiết tuyến'!$AA:$AA,Master!$G20,'Chi tiết tuyến'!P:P,"x",'Chi tiết tuyến'!$W:$W,"x"),"") | AI20: =IF($G20<>"",SUMIFS('Chi tiết tuyến'!$BE:$BE,'Chi tiết tuyến'!$AA:$AA,Master!$G20,'Chi tiết tuyến'!$W:$W,"x"),"") | AJ20: =IF($G20<>"",COUNTIFS('Chi tiết tuyến'!$AA:$AA,Master!$G20,'Chi tiết tuyến'!Q:Q,"x",'Chi tiết tuyến'!$W:$W,"x"),"") | AK20: =IF($G20<>"",SUMIFS('Chi tiết tuyến'!$BF:$BF,'Chi tiết tuyến'!$AA:$AA,Master!$G20,'Chi tiết tuyến'!$W:$W,"x"),"") | AL20: =IF($G20<>"",SUM(Z20,AB20,AD20,AF20,AH20,AJ20),"") | AM20: =IF($G20<>"",SUM(AA20,AC20,AE20,AG20,AI20,AK20),"") | AN20: =IF($G20<>"",COUNTIFS('Chi tiết tuyến'!$AA:$AA,Master!$G20,'Chi tiết tuyến'!L:L,"x",'Chi tiết tuyến'!$X:$X,"x"),"") | AO20: =IF($G20<>"",SUMIFS('Chi tiết tuyến'!$BA:$BA,'Chi tiết tuyến'!$AA:$AA,Master!$G20,'Chi tiết tuyến'!$X:$X,"x"),"") | AP20: =IF($G20<>"",COUNTIFS('Chi tiết tuyến'!$AA:$AA,Master!$G20,'Chi tiết tuyến'!M:M,"x",'Chi tiết tuyến'!$X:$X,"x"),"") | AQ20: =IF($G20<>"",SUMIFS('Chi tiết tuyến'!$BB:$BB,'Chi tiết tuyến'!$AA:$AA,Master!$G20,'Chi tiết tuyến'!$X:$X,"x"),"") | AR20: =IF($G20<>"",COUNTIFS('Chi tiết tuyến'!$AA:$AA,Master!$G20,'Chi tiết tuyến'!N:N,"x",'Chi tiết tuyến'!$X:$X,"x"),"") | AS20: =IF($G20<>"",SUMIFS('Chi tiết tuyến'!$BC:$BC,'Chi tiết tuyến'!$AA:$AA,Master!$G20,'Chi tiết tuyến'!$X:$X,"x"),"") | AT20: =IF($G20<>"",COUNTIFS('Chi tiết tuyến'!$AA:$AA,Master!$G20,'Chi tiết tuyến'!O:O,"x",'Chi tiết tuyến'!$X:$X,"x"),"") | AU20: =IF($G20<>"",SUMIFS('Chi tiết tuyến'!$BD:$BD,'Chi tiết tuyến'!$AA:$AA,Master!$G20,'Chi tiết tuyến'!$X:$X,"x"),"") | AV20: =IF($G20<>"",COUNTIFS('Chi tiết tuyến'!$AA:$AA,Master!$G20,'Chi tiết tuyến'!P:P,"x",'Chi tiết tuyến'!$X:$X,"x"),"") | AW20: =IF($G20<>"",SUMIFS('Chi tiết tuyến'!$BE:$BE,'Chi tiết tuyến'!$AA:$AA,Master!$G20,'Chi tiết tuyến'!$X:$X,"x"),"") | AX20: =IF($G20<>"",COUNTIFS('Chi tiết tuyến'!$AA:$AA,Master!$G20,'Chi tiết tuyến'!Q:Q,"x",'Chi tiết tuyến'!$X:$X,"x"),"") | AY20: =IF($G20<>"",SUMIFS('Chi tiết tuyến'!$BF:$BF,'Chi tiết tuyến'!$AA:$AA,Master!$G20,'Chi tiết tuyến'!$X:$X,"x"),"") | AZ20: =IF($G20<>"",SUM(AN20,AP20,AR20,AT20,AV20,AX20),"") | BA20: =IF($G20<>"",SUM(AO20,AQ20,AS20,AU20,AW20,AY20),"") | BB20: =COUNTIFS('Chi tiết tuyến'!$AA:$AA,Master!$G20,'Chi tiết tuyến'!L:L,"x",'Chi tiết tuyến'!$Y:$Y,"x") -> 0 | BC20: =SUMIFS('Chi tiết tuyến'!$BA:$BA,'Chi tiết tuyến'!$AA:$AA,Master!$G20,'Chi tiết tuyến'!$W:$W,"x") -> 0 | BD20: =COUNTIFS('Chi tiết tuyến'!$AA:$AA,Master!$G20,'Chi tiết tuyến'!M:M,"x",'Chi tiết tuyến'!$Y:$Y,"x") -> 0 | BE20: =SUMIFS('Chi tiết tuyến'!$BB:$BB,'Chi tiết tuyến'!$AA:$AA,Master!$G20,'Chi tiết tuyến'!$W:$W,"x") -> 0 | BF20: =COUNTIFS('Chi tiết tuyến'!$AA:$AA,Master!$G20,'Chi tiết tuyến'!N:N,"x",'Chi tiết tuyến'!$Y:$Y,"x") -> 0 | BG20: =SUMIFS('Chi tiết tuyến'!$BC:$BC,'Chi tiết tuyến'!$AA:$AA,Master!$G20,'Chi tiết tuyến'!$W:$W,"x") -> 0 | BH20: =COUNTIFS('Chi tiết tuyến'!$AA:$AA,Master!$G20,'Chi tiết tuyến'!O:O,"x",'Chi tiết tuyến'!$Y:$Y,"x") -> 0 | BI20: =SUMIFS('Chi tiết tuyến'!$BD:$BD,'Chi tiết tuyến'!$AA:$AA,Master!$G20,'Chi tiết tuyến'!$W:$W,"x") -> 0 | BJ20: =COUNTIFS('Chi tiết tuyến'!$AA:$AA,Master!$G20,'Chi tiết tuyến'!P:P,"x",'Chi tiết tuyến'!$Y:$Y,"x") -> 0 | BK20: =SUMIFS('Chi tiết tuyến'!$BE:$BE,'Chi tiết tuyến'!$AA:$AA,Master!$G20,'Chi tiết tuyến'!$W:$W,"x") -> 0 | BL20: =COUNTIFS('Chi tiết tuyến'!$AA:$AA,Master!$G20,'Chi tiết tuyến'!Q:Q,"x",'Chi tiết tuyến'!$Y:$Y,"x") -> 0 | BM20: =SUMIFS('Chi tiết tuyến'!$BF:$BF,'Chi tiết tuyến'!$AA:$AA,Master!$G20,'Chi tiết tuyến'!$W:$W,"x") -> 0 | BN20: =SUM(BB20,BD20,BF20,BH20,BJ20,BL20) -> 0 | BO20: =SUM(BC20,BE20,BG20,BI20,BK20,BM20) -> 0 | BP20: =COUNTIFS('Chi tiết tuyến'!$AA:$AA,Master!$G20,'Chi tiết tuyến'!L:L,"x",'Chi tiết tuyến'!$Z:$Z,"x") -> 0 | BQ20: =SUMIFS('Chi tiết tuyến'!$BA:$BA,'Chi tiết tuyến'!$AA:$AA,Master!$G20,'Chi tiết tuyến'!$X:$X,"x") -> 0 | BR20: =COUNTIFS('Chi tiết tuyến'!$AA:$AA,Master!$G20,'Chi tiết tuyến'!M:M,"x",'Chi tiết tuyến'!$Z:$Z,"x") -> 0 | BS20: =SUMIFS('Chi tiết tuyến'!$BB:$BB,'Chi tiết tuyến'!$AA:$AA,Master!$G20,'Chi tiết tuyến'!$X:$X,"x") -> 0 | BT20: =COUNTIFS('Chi tiết tuyến'!$AA:$AA,Master!$G20,'Chi tiết tuyến'!N:N,"x",'Chi tiết tuyến'!$Z:$Z,"x") -> 0 | BU20: =SUMIFS('Chi tiết tuyến'!$BC:$BC,'Chi tiết tuyến'!$AA:$AA,Master!$G20,'Chi tiết tuyến'!$X:$X,"x") -> 0 | BV20: =COUNTIFS('Chi tiết tuyến'!$AA:$AA,Master!$G20,'Chi tiết tuyến'!O:O,"x",'Chi tiết tuyến'!$Z:$Z,"x") -> 0 | BW20: =SUMIFS('Chi tiết tuyến'!$BD:$BD,'Chi tiết tuyến'!$AA:$AA,Master!$G20,'Chi tiết tuyến'!$X:$X,"x") -> 0 | BX20: =COUNTIFS('Chi tiết tuyến'!$AA:$AA,Master!$G20,'Chi tiết tuyến'!P:P,"x",'Chi tiết tuyến'!$Z:$Z,"x") -> 0 | BY20: =SUMIFS('Chi tiết tuyến'!$BE:$BE,'Chi tiết tuyến'!$AA:$AA,Master!$G20,'Chi tiết tuyến'!$X:$X,"x") -> 0 | BZ20: =COUNTIFS('Chi tiết tuyến'!$AA:$AA,Master!$G20,'Chi tiết tuyến'!Q:Q,"x",'Chi tiết tuyến'!$Z:$Z,"x") -> 0 | CA20: =SUMIFS('Chi tiết tuyến'!$BF:$BF,'Chi tiết tuyến'!$AA:$AA,Master!$G20,'Chi tiết tuyến'!$X:$X,"x") -> 0 | CB20: =SUM(BP20,BR20,BT20,BV20,BX20,BZ20) -> 0 | CC20: =SUM(BQ20,BS20,BU20,BW20,BY20,CA20) -> 0
F21: =IF(AND(F20>0,G21<>""),F20+1,"") | I21: =IF($G21<>"",SUMIFS('Chi tiết tuyến'!$AE:$AE,'Chi tiết tuyến'!$AD:$AD,Master!I$1,'Chi tiết tuyến'!$AA:$AA,Master!$G21),"") | J21: =IF($G21<>"",SUMIFS('Chi tiết tuyến'!$AE:$AE,'Chi tiết tuyến'!$AD:$AD,Master!J$1,'Chi tiết tuyến'!$AA:$AA,Master!$G21),"") | K21: =IF($G21<>"",SUM(I21:J21),"") | L21: =IF($G21<>"",COUNTIFS('Chi tiết tuyến'!$AA:$AA,Master!$G21,'Chi tiết tuyến'!$AD:$AD,Master!L$1),"") | M21: =IF($G21<>"",COUNTIFS('Chi tiết tuyến'!$AA:$AA,Master!$G21,'Chi tiết tuyến'!$AD:$AD,Master!M$1),"") | N21: =IF($G21<>"",SUM(L21:M21),"") | O21: =IF($G21<>"",VLOOKUP($G21,'Tuyến và nhân viên'!$I:$S,9,0),"") | P21: =IF($G21<>"",VLOOKUP($G21,'Tuyến và nhân viên'!$I:$S,10,0),"") | Q21: =IF($G21<>"",VLOOKUP($G21,'Tuyến và nhân viên'!$I:$S,11,0),"") | R21: =IF($G21<>"",SUMIFS('Chi tiết tuyến'!$AJ:$AJ,'Chi tiết tuyến'!$AA:$AA,Master!$G21),"") | S21: =IF($G21<>"",_xlfn.MINIFS(Z21:CC21,$Z$15:$CC$15,"# KH"),"") | T21: =IF($G21<>"",_xlfn.MAXIFS(Z21:CC21,$Z$15:$CC$15,"# KH"),"") | U21: =IF($G21<>"",COUNTIFS('Chi tiết tuyến'!$AG:$AG,U$2,'Chi tiết tuyến'!$AA:$AA,Master!$G21),"") | V21: =IF($G21<>"",COUNTIFS('Chi tiết tuyến'!$AG:$AG,V$2,'Chi tiết tuyến'!$AA:$AA,Master!$G21),"") | W21: =IF($G21<>"",COUNTIFS('Chi tiết tuyến'!$AG:$AG,W$2,'Chi tiết tuyến'!$AA:$AA,Master!$G21),"") | X21: =IF($G21<>"",COUNTIFS('Chi tiết tuyến'!$AH:$AH,FALSE,'Chi tiết tuyến'!$AA:$AA,Master!$G21),"") | Y21: =IF($G21<>"",COUNTIFS('Chi tiết tuyến'!$AI:$AI,FALSE,'Chi tiết tuyến'!$AA:$AA,Master!$G21),"") | Z21: =IF($G21<>"",COUNTIFS('Chi tiết tuyến'!$AA:$AA,Master!$G21,'Chi tiết tuyến'!L:L,"x",'Chi tiết tuyến'!$W:$W,"x"),"") | AA21: =IF($G21<>"",SUMIFS('Chi tiết tuyến'!$BA:$BA,'Chi tiết tuyến'!$AA:$AA,Master!$G21,'Chi tiết tuyến'!$W:$W,"x"),"") | AB21: =IF($G21<>"",COUNTIFS('Chi tiết tuyến'!$AA:$AA,Master!$G21,'Chi tiết tuyến'!M:M,"x",'Chi tiết tuyến'!$W:$W,"x"),"") | AC21: =IF($G21<>"",SUMIFS('Chi tiết tuyến'!$BB:$BB,'Chi tiết tuyến'!$AA:$AA,Master!$G21,'Chi tiết tuyến'!$W:$W,"x"),"") | AD21: =IF($G21<>"",COUNTIFS('Chi tiết tuyến'!$AA:$AA,Master!$G21,'Chi tiết tuyến'!N:N,"x",'Chi tiết tuyến'!$W:$W,"x"),"") | AE21: =IF($G21<>"",SUMIFS('Chi tiết tuyến'!$BC:$BC,'Chi tiết tuyến'!$AA:$AA,Master!$G21,'Chi tiết tuyến'!$W:$W,"x"),"") | AF21: =IF($G21<>"",COUNTIFS('Chi tiết tuyến'!$AA:$AA,Master!$G21,'Chi tiết tuyến'!O:O,"x",'Chi tiết tuyến'!$W:$W,"x"),"") | AG21: =IF($G21<>"",SUMIFS('Chi tiết tuyến'!$BD:$BD,'Chi tiết tuyến'!$AA:$AA,Master!$G21,'Chi tiết tuyến'!$W:$W,"x"),"") | AH21: =IF($G21<>"",COUNTIFS('Chi tiết tuyến'!$AA:$AA,Master!$G21,'Chi tiết tuyến'!P:P,"x",'Chi tiết tuyến'!$W:$W,"x"),"") | AI21: =IF($G21<>"",SUMIFS('Chi tiết tuyến'!$BE:$BE,'Chi tiết tuyến'!$AA:$AA,Master!$G21,'Chi tiết tuyến'!$W:$W,"x"),"") | AJ21: =IF($G21<>"",COUNTIFS('Chi tiết tuyến'!$AA:$AA,Master!$G21,'Chi tiết tuyến'!Q:Q,"x",'Chi tiết tuyến'!$W:$W,"x"),"") | AK21: =IF($G21<>"",SUMIFS('Chi tiết tuyến'!$BF:$BF,'Chi tiết tuyến'!$AA:$AA,Master!$G21,'Chi tiết tuyến'!$W:$W,"x"),"") | AL21: =IF($G21<>"",SUM(Z21,AB21,AD21,AF21,AH21,AJ21),"") | AM21: =IF($G21<>"",SUM(AA21,AC21,AE21,AG21,AI21,AK21),"") | AN21: =IF($G21<>"",COUNTIFS('Chi tiết tuyến'!$AA:$AA,Master!$G21,'Chi tiết tuyến'!L:L,"x",'Chi tiết tuyến'!$X:$X,"x"),"") | AO21: =IF($G21<>"",SUMIFS('Chi tiết tuyến'!$BA:$BA,'Chi tiết tuyến'!$AA:$AA,Master!$G21,'Chi tiết tuyến'!$X:$X,"x"),"") | AP21: =IF($G21<>"",COUNTIFS('Chi tiết tuyến'!$AA:$AA,Master!$G21,'Chi tiết tuyến'!M:M,"x",'Chi tiết tuyến'!$X:$X,"x"),"") | AQ21: =IF($G21<>"",SUMIFS('Chi tiết tuyến'!$BB:$BB,'Chi tiết tuyến'!$AA:$AA,Master!$G21,'Chi tiết tuyến'!$X:$X,"x"),"") | AR21: =IF($G21<>"",COUNTIFS('Chi tiết tuyến'!$AA:$AA,Master!$G21,'Chi tiết tuyến'!N:N,"x",'Chi tiết tuyến'!$X:$X,"x"),"") | AS21: =IF($G21<>"",SUMIFS('Chi tiết tuyến'!$BC:$BC,'Chi tiết tuyến'!$AA:$AA,Master!$G21,'Chi tiết tuyến'!$X:$X,"x"),"") | AT21: =IF($G21<>"",COUNTIFS('Chi tiết tuyến'!$AA:$AA,Master!$G21,'Chi tiết tuyến'!O:O,"x",'Chi tiết tuyến'!$X:$X,"x"),"") | AU21: =IF($G21<>"",SUMIFS('Chi tiết tuyến'!$BD:$BD,'Chi tiết tuyến'!$AA:$AA,Master!$G21,'Chi tiết tuyến'!$X:$X,"x"),"") | AV21: =IF($G21<>"",COUNTIFS('Chi tiết tuyến'!$AA:$AA,Master!$G21,'Chi tiết tuyến'!P:P,"x",'Chi tiết tuyến'!$X:$X,"x"),"") | AW21: =IF($G21<>"",SUMIFS('Chi tiết tuyến'!$BE:$BE,'Chi tiết tuyến'!$AA:$AA,Master!$G21,'Chi tiết tuyến'!$X:$X,"x"),"") | AX21: =IF($G21<>"",COUNTIFS('Chi tiết tuyến'!$AA:$AA,Master!$G21,'Chi tiết tuyến'!Q:Q,"x",'Chi tiết tuyến'!$X:$X,"x"),"") | AY21: =IF($G21<>"",SUMIFS('Chi tiết tuyến'!$BF:$BF,'Chi tiết tuyến'!$AA:$AA,Master!$G21,'Chi tiết tuyến'!$X:$X,"x"),"") | AZ21: =IF($G21<>"",SUM(AN21,AP21,AR21,AT21,AV21,AX21),"") | BA21: =IF($G21<>"",SUM(AO21,AQ21,AS21,AU21,AW21,AY21),"") | BB21: =COUNTIFS('Chi tiết tuyến'!$AA:$AA,Master!$G21,'Chi tiết tuyến'!L:L,"x",'Chi tiết tuyến'!$Y:$Y,"x") -> 0 | BC21: =SUMIFS('Chi tiết tuyến'!$BA:$BA,'Chi tiết tuyến'!$AA:$AA,Master!$G21,'Chi tiết tuyến'!$W:$W,"x") -> 0 | BD21: =COUNTIFS('Chi tiết tuyến'!$AA:$AA,Master!$G21,'Chi tiết tuyến'!M:M,"x",'Chi tiết tuyến'!$Y:$Y,"x") -> 0 | BE21: =SUMIFS('Chi tiết tuyến'!$BB:$BB,'Chi tiết tuyến'!$AA:$AA,Master!$G21,'Chi tiết tuyến'!$W:$W,"x") -> 0 | BF21: =COUNTIFS('Chi tiết tuyến'!$AA:$AA,Master!$G21,'Chi tiết tuyến'!N:N,"x",'Chi tiết tuyến'!$Y:$Y,"x") -> 0 | BG21: =SUMIFS('Chi tiết tuyến'!$BC:$BC,'Chi tiết tuyến'!$AA:$AA,Master!$G21,'Chi tiết tuyến'!$W:$W,"x") -> 0 | BH21: =COUNTIFS('Chi tiết tuyến'!$AA:$AA,Master!$G21,'Chi tiết tuyến'!O:O,"x",'Chi tiết tuyến'!$Y:$Y,"x") -> 0 | BI21: =SUMIFS('Chi tiết tuyến'!$BD:$BD,'Chi tiết tuyến'!$AA:$AA,Master!$G21,'Chi tiết tuyến'!$W:$W,"x") -> 0 | BJ21: =COUNTIFS('Chi tiết tuyến'!$AA:$AA,Master!$G21,'Chi tiết tuyến'!P:P,"x",'Chi tiết tuyến'!$Y:$Y,"x") -> 0 | BK21: =SUMIFS('Chi tiết tuyến'!$BE:$BE,'Chi tiết tuyến'!$AA:$AA,Master!$G21,'Chi tiết tuyến'!$W:$W,"x") -> 0 | BL21: =COUNTIFS('Chi tiết tuyến'!$AA:$AA,Master!$G21,'Chi tiết tuyến'!Q:Q,"x",'Chi tiết tuyến'!$Y:$Y,"x") -> 0 | BM21: =SUMIFS('Chi tiết tuyến'!$BF:$BF,'Chi tiết tuyến'!$AA:$AA,Master!$G21,'Chi tiết tuyến'!$W:$W,"x") -> 0 | BN21: =SUM(BB21,BD21,BF21,BH21,BJ21,BL21) -> 0 | BO21: =SUM(BC21,BE21,BG21,BI21,BK21,BM21) -> 0 | BP21: =COUNTIFS('Chi tiết tuyến'!$AA:$AA,Master!$G21,'Chi tiết tuyến'!L:L,"x",'Chi tiết tuyến'!$Z:$Z,"x") -> 0 | BQ21: =SUMIFS('Chi tiết tuyến'!$BA:$BA,'Chi tiết tuyến'!$AA:$AA,Master!$G21,'Chi tiết tuyến'!$X:$X,"x") -> 0 | BR21: =COUNTIFS('Chi tiết tuyến'!$AA:$AA,Master!$G21,'Chi tiết tuyến'!M:M,"x",'Chi tiết tuyến'!$Z:$Z,"x") -> 0 | BS21: =SUMIFS('Chi tiết tuyến'!$BB:$BB,'Chi tiết tuyến'!$AA:$AA,Master!$G21,'Chi tiết tuyến'!$X:$X,"x") -> 0 | BT21: =COUNTIFS('Chi tiết tuyến'!$AA:$AA,Master!$G21,'Chi tiết tuyến'!N:N,"x",'Chi tiết tuyến'!$Z:$Z,"x") -> 0 | BU21: =SUMIFS('Chi tiết tuyến'!$BC:$BC,'Chi tiết tuyến'!$AA:$AA,Master!$G21,'Chi tiết tuyến'!$X:$X,"x") -> 0 | BV21: =COUNTIFS('Chi tiết tuyến'!$AA:$AA,Master!$G21,'Chi tiết tuyến'!O:O,"x",'Chi tiết tuyến'!$Z:$Z,"x") -> 0 | BW21: =SUMIFS('Chi tiết tuyến'!$BD:$BD,'Chi tiết tuyến'!$AA:$AA,Master!$G21,'Chi tiết tuyến'!$X:$X,"x") -> 0 | BX21: =COUNTIFS('Chi tiết tuyến'!$AA:$AA,Master!$G21,'Chi tiết tuyến'!P:P,"x",'Chi tiết tuyến'!$Z:$Z,"x") -> 0 | BY21: =SUMIFS('Chi tiết tuyến'!$BE:$BE,'Chi tiết tuyến'!$AA:$AA,Master!$G21,'Chi tiết tuyến'!$X:$X,"x") -> 0 | BZ21: =COUNTIFS('Chi tiết tuyến'!$AA:$AA,Master!$G21,'Chi tiết tuyến'!Q:Q,"x",'Chi tiết tuyến'!$Z:$Z,"x") -> 0 | CA21: =SUMIFS('Chi tiết tuyến'!$BF:$BF,'Chi tiết tuyến'!$AA:$AA,Master!$G21,'Chi tiết tuyến'!$X:$X,"x") -> 0 | CB21: =SUM(BP21,BR21,BT21,BV21,BX21,BZ21) -> 0 | CC21: =SUM(BQ21,BS21,BU21,BW21,BY21,CA21) -> 0
F22: =IF(AND(F21>0,G22<>""),F21+1,"") | I22: =IF($G22<>"",SUMIFS('Chi tiết tuyến'!$AE:$AE,'Chi tiết tuyến'!$AD:$AD,Master!I$1,'Chi tiết tuyến'!$AA:$AA,Master!$G22),"") | J22: =IF($G22<>"",SUMIFS('Chi tiết tuyến'!$AE:$AE,'Chi tiết tuyến'!$AD:$AD,Master!J$1,'Chi tiết tuyến'!$AA:$AA,Master!$G22),"") | K22: =IF($G22<>"",SUM(I22:J22),"") | L22: =IF($G22<>"",COUNTIFS('Chi tiết tuyến'!$AA:$AA,Master!$G22,'Chi tiết tuyến'!$AD:$AD,Master!L$1),"") | M22: =IF($G22<>"",COUNTIFS('Chi tiết tuyến'!$AA:$AA,Master!$G22,'Chi tiết tuyến'!$AD:$AD,Master!M$1),"") | N22: =IF($G22<>"",SUM(L22:M22),"") | O22: =IF($G22<>"",VLOOKUP($G22,'Tuyến và nhân viên'!$I:$S,9,0),"") | P22: =IF($G22<>"",VLOOKUP($G22,'Tuyến và nhân viên'!$I:$S,10,0),"") | Q22: =IF($G22<>"",VLOOKUP($G22,'Tuyến và nhân viên'!$I:$S,11,0),"") | R22: =IF($G22<>"",SUMIFS('Chi tiết tuyến'!$AJ:$AJ,'Chi tiết tuyến'!$AA:$AA,Master!$G22),"") | S22: =IF($G22<>"",_xlfn.MINIFS(Z22:CC22,$Z$15:$CC$15,"# KH"),"") | T22: =IF($G22<>"",_xlfn.MAXIFS(Z22:CC22,$Z$15:$CC$15,"# KH"),"") | U22: =IF($G22<>"",COUNTIFS('Chi tiết tuyến'!$AG:$AG,U$2,'Chi tiết tuyến'!$AA:$AA,Master!$G22),"") | V22: =IF($G22<>"",COUNTIFS('Chi tiết tuyến'!$AG:$AG,V$2,'Chi tiết tuyến'!$AA:$AA,Master!$G22),"") | W22: =IF($G22<>"",COUNTIFS('Chi tiết tuyến'!$AG:$AG,W$2,'Chi tiết tuyến'!$AA:$AA,Master!$G22),"") | X22: =IF($G22<>"",COUNTIFS('Chi tiết tuyến'!$AH:$AH,FALSE,'Chi tiết tuyến'!$AA:$AA,Master!$G22),"") | Y22: =IF($G22<>"",COUNTIFS('Chi tiết tuyến'!$AI:$AI,FALSE,'Chi tiết tuyến'!$AA:$AA,Master!$G22),"") | Z22: =IF($G22<>"",COUNTIFS('Chi tiết tuyến'!$AA:$AA,Master!$G22,'Chi tiết tuyến'!L:L,"x",'Chi tiết tuyến'!$W:$W,"x"),"") | AA22: =IF($G22<>"",SUMIFS('Chi tiết tuyến'!$BA:$BA,'Chi tiết tuyến'!$AA:$AA,Master!$G22,'Chi tiết tuyến'!$W:$W,"x"),"") | AB22: =IF($G22<>"",COUNTIFS('Chi tiết tuyến'!$AA:$AA,Master!$G22,'Chi tiết tuyến'!M:M,"x",'Chi tiết tuyến'!$W:$W,"x"),"") | AC22: =IF($G22<>"",SUMIFS('Chi tiết tuyến'!$BB:$BB,'Chi tiết tuyến'!$AA:$AA,Master!$G22,'Chi tiết tuyến'!$W:$W,"x"),"") | AD22: =IF($G22<>"",COUNTIFS('Chi tiết tuyến'!$AA:$AA,Master!$G22,'Chi tiết tuyến'!N:N,"x",'Chi tiết tuyến'!$W:$W,"x"),"") | AE22: =IF($G22<>"",SUMIFS('Chi tiết tuyến'!$BC:$BC,'Chi tiết tuyến'!$AA:$AA,Master!$G22,'Chi tiết tuyến'!$W:$W,"x"),"") | AF22: =IF($G22<>"",COUNTIFS('Chi tiết tuyến'!$AA:$AA,Master!$G22,'Chi tiết tuyến'!O:O,"x",'Chi tiết tuyến'!$W:$W,"x"),"") | AG22: =IF($G22<>"",SUMIFS('Chi tiết tuyến'!$BD:$BD,'Chi tiết tuyến'!$AA:$AA,Master!$G22,'Chi tiết tuyến'!$W:$W,"x"),"") | AH22: =IF($G22<>"",COUNTIFS('Chi tiết tuyến'!$AA:$AA,Master!$G22,'Chi tiết tuyến'!P:P,"x",'Chi tiết tuyến'!$W:$W,"x"),"") | AI22: =IF($G22<>"",SUMIFS('Chi tiết tuyến'!$BE:$BE,'Chi tiết tuyến'!$AA:$AA,Master!$G22,'Chi tiết tuyến'!$W:$W,"x"),"") | AJ22: =IF($G22<>"",COUNTIFS('Chi tiết tuyến'!$AA:$AA,Master!$G22,'Chi tiết tuyến'!Q:Q,"x",'Chi tiết tuyến'!$W:$W,"x"),"") | AK22: =IF($G22<>"",SUMIFS('Chi tiết tuyến'!$BF:$BF,'Chi tiết tuyến'!$AA:$AA,Master!$G22,'Chi tiết tuyến'!$W:$W,"x"),"") | AL22: =IF($G22<>"",SUM(Z22,AB22,AD22,AF22,AH22,AJ22),"") | AM22: =IF($G22<>"",SUM(AA22,AC22,AE22,AG22,AI22,AK22),"") | AN22: =IF($G22<>"",COUNTIFS('Chi tiết tuyến'!$AA:$AA,Master!$G22,'Chi tiết tuyến'!L:L,"x",'Chi tiết tuyến'!$X:$X,"x"),"") | AO22: =IF($G22<>"",SUMIFS('Chi tiết tuyến'!$BA:$BA,'Chi tiết tuyến'!$AA:$AA,Master!$G22,'Chi tiết tuyến'!$X:$X,"x"),"") | AP22: =IF($G22<>"",COUNTIFS('Chi tiết tuyến'!$AA:$AA,Master!$G22,'Chi tiết tuyến'!M:M,"x",'Chi tiết tuyến'!$X:$X,"x"),"") | AQ22: =IF($G22<>"",SUMIFS('Chi tiết tuyến'!$BB:$BB,'Chi tiết tuyến'!$AA:$AA,Master!$G22,'Chi tiết tuyến'!$X:$X,"x"),"") | AR22: =IF($G22<>"",COUNTIFS('Chi tiết tuyến'!$AA:$AA,Master!$G22,'Chi tiết tuyến'!N:N,"x",'Chi tiết tuyến'!$X:$X,"x"),"") | AS22: =IF($G22<>"",SUMIFS('Chi tiết tuyến'!$BC:$BC,'Chi tiết tuyến'!$AA:$AA,Master!$G22,'Chi tiết tuyến'!$X:$X,"x"),"") | AT22: =IF($G22<>"",COUNTIFS('Chi tiết tuyến'!$AA:$AA,Master!$G22,'Chi tiết tuyến'!O:O,"x",'Chi tiết tuyến'!$X:$X,"x"),"") | AU22: =IF($G22<>"",SUMIFS('Chi tiết tuyến'!$BD:$BD,'Chi tiết tuyến'!$AA:$AA,Master!$G22,'Chi tiết tuyến'!$X:$X,"x"),"") | AV22: =IF($G22<>"",COUNTIFS('Chi tiết tuyến'!$AA:$AA,Master!$G22,'Chi tiết tuyến'!P:P,"x",'Chi tiết tuyến'!$X:$X,"x"),"") | AW22: =IF($G22<>"",SUMIFS('Chi tiết tuyến'!$BE:$BE,'Chi tiết tuyến'!$AA:$AA,Master!$G22,'Chi tiết tuyến'!$X:$X,"x"),"") | AX22: =IF($G22<>"",COUNTIFS('Chi tiết tuyến'!$AA:$AA,Master!$G22,'Chi tiết tuyến'!Q:Q,"x",'Chi tiết tuyến'!$X:$X,"x"),"") | AY22: =IF($G22<>"",SUMIFS('Chi tiết tuyến'!$BF:$BF,'Chi tiết tuyến'!$AA:$AA,Master!$G22,'Chi tiết tuyến'!$X:$X,"x"),"") | AZ22: =IF($G22<>"",SUM(AN22,AP22,AR22,AT22,AV22,AX22),"") | BA22: =IF($G22<>"",SUM(AO22,AQ22,AS22,AU22,AW22,AY22),"") | BB22: =COUNTIFS('Chi tiết tuyến'!$AA:$AA,Master!$G22,'Chi tiết tuyến'!L:L,"x",'Chi tiết tuyến'!$Y:$Y,"x") -> 0 | BC22: =SUMIFS('Chi tiết tuyến'!$BA:$BA,'Chi tiết tuyến'!$AA:$AA,Master!$G22,'Chi tiết tuyến'!$W:$W,"x") -> 0 | BD22: =COUNTIFS('Chi tiết tuyến'!$AA:$AA,Master!$G22,'Chi tiết tuyến'!M:M,"x",'Chi tiết tuyến'!$Y:$Y,"x") -> 0 | BE22: =SUMIFS('Chi tiết tuyến'!$BB:$BB,'Chi tiết tuyến'!$AA:$AA,Master!$G22,'Chi tiết tuyến'!$W:$W,"x") -> 0 | BF22: =COUNTIFS('Chi tiết tuyến'!$AA:$AA,Master!$G22,'Chi tiết tuyến'!N:N,"x",'Chi tiết tuyến'!$Y:$Y,"x") -> 0 | BG22: =SUMIFS('Chi tiết tuyến'!$BC:$BC,'Chi tiết tuyến'!$AA:$AA,Master!$G22,'Chi tiết tuyến'!$W:$W,"x") -> 0 | BH22: =COUNTIFS('Chi tiết tuyến'!$AA:$AA,Master!$G22,'Chi tiết tuyến'!O:O,"x",'Chi tiết tuyến'!$Y:$Y,"x") -> 0 | BI22: =SUMIFS('Chi tiết tuyến'!$BD:$BD,'Chi tiết tuyến'!$AA:$AA,Master!$G22,'Chi tiết tuyến'!$W:$W,"x") -> 0 | BJ22: =COUNTIFS('Chi tiết tuyến'!$AA:$AA,Master!$G22,'Chi tiết tuyến'!P:P,"x",'Chi tiết tuyến'!$Y:$Y,"x") -> 0 | BK22: =SUMIFS('Chi tiết tuyến'!$BE:$BE,'Chi tiết tuyến'!$AA:$AA,Master!$G22,'Chi tiết tuyến'!$W:$W,"x") -> 0 | BL22: =COUNTIFS('Chi tiết tuyến'!$AA:$AA,Master!$G22,'Chi tiết tuyến'!Q:Q,"x",'Chi tiết tuyến'!$Y:$Y,"x") -> 0 | BM22: =SUMIFS('Chi tiết tuyến'!$BF:$BF,'Chi tiết tuyến'!$AA:$AA,Master!$G22,'Chi tiết tuyến'!$W:$W,"x") -> 0 | BN22: =SUM(BB22,BD22,BF22,BH22,BJ22,BL22) -> 0 | BO22: =SUM(BC22,BE22,BG22,BI22,BK22,BM22) -> 0 | BP22: =COUNTIFS('Chi tiết tuyến'!$AA:$AA,Master!$G22,'Chi tiết tuyến'!L:L,"x",'Chi tiết tuyến'!$Z:$Z,"x") -> 0 | BQ22: =SUMIFS('Chi tiết tuyến'!$BA:$BA,'Chi tiết tuyến'!$AA:$AA,Master!$G22,'Chi tiết tuyến'!$X:$X,"x") -> 0 | BR22: =COUNTIFS('Chi tiết tuyến'!$AA:$AA,Master!$G22,'Chi tiết tuyến'!M:M,"x",'Chi tiết tuyến'!$Z:$Z,"x") -> 0 | BS22: =SUMIFS('Chi tiết tuyến'!$BB:$BB,'Chi tiết tuyến'!$AA:$AA,Master!$G22,'Chi tiết tuyến'!$X:$X,"x") -> 0 | BT22: =COUNTIFS('Chi tiết tuyến'!$AA:$AA,Master!$G22,'Chi tiết tuyến'!N:N,"x",'Chi tiết tuyến'!$Z:$Z,"x") -> 0 | BU22: =SUMIFS('Chi tiết tuyến'!$BC:$BC,'Chi tiết tuyến'!$AA:$AA,Master!$G22,'Chi tiết tuyến'!$X:$X,"x") -> 0 | BV22: =COUNTIFS('Chi tiết tuyến'!$AA:$AA,Master!$G22,'Chi tiết tuyến'!O:O,"x",'Chi tiết tuyến'!$Z:$Z,"x") -> 0 | BW22: =SUMIFS('Chi tiết tuyến'!$BD:$BD,'Chi tiết tuyến'!$AA:$AA,Master!$G22,'Chi tiết tuyến'!$X:$X,"x") -> 0 | BX22: =COUNTIFS('Chi tiết tuyến'!$AA:$AA,Master!$G22,'Chi tiết tuyến'!P:P,"x",'Chi tiết tuyến'!$Z:$Z,"x") -> 0 | BY22: =SUMIFS('Chi tiết tuyến'!$BE:$BE,'Chi tiết tuyến'!$AA:$AA,Master!$G22,'Chi tiết tuyến'!$X:$X,"x") -> 0 | BZ22: =COUNTIFS('Chi tiết tuyến'!$AA:$AA,Master!$G22,'Chi tiết tuyến'!Q:Q,"x",'Chi tiết tuyến'!$Z:$Z,"x") -> 0 | CA22: =SUMIFS('Chi tiết tuyến'!$BF:$BF,'Chi tiết tuyến'!$AA:$AA,Master!$G22,'Chi tiết tuyến'!$X:$X,"x") -> 0 | CB22: =SUM(BP22,BR22,BT22,BV22,BX22,BZ22) -> 0 | CC22: =SUM(BQ22,BS22,BU22,BW22,BY22,CA22) -> 0
